<?xml version="1.0" ?>
<!-- =================================================================================== -->
<!-- |    This document was autogenerated by xacro from /home/captain-yoshi/ws/ros/oscar_ws/src/oscar_robot_setup/oscar_robot_setup_description/urdf/oscar_ur3_lab3023.xacro | -->
<!-- |    EDITING THIS FILE BY HAND IS NOT RECOMMENDED                                 | -->
<!-- =================================================================================== -->
<robot name="oscar_ur3_lab3023">
    <material name="aluminum">
        <color rgba="0.5 0.5 0.5 1" />
    </material>
    <material name="plastic">
        <color rgba="0.1 0.1 0.1 1" />
    </material>
    <!-- TCP calibration of the robotiq gripper (xyz)-->
    <!-- <xacro:property name="tcp_calibration_gripper" value="0.0010977079105917165 -0.00047849967130053628 -2.3860966923898729e-05" /> -->
    <!-- Floor -->
    <link name="floor">
        <collision>
            <origin rpy="0 0 0" xyz="0 0 0" />
            <geometry>
                <box size="1.3292 1.6342 0.0254" />
            </geometry>
        </collision>
        <inertial>
            <mass value="0.1" />
            <origin xyz="0 0 0" rpy="0 0 0" />
            <inertia ixx="0.03" iyy="0.03" izz="0.03" ixy="0.0" ixz="0.0" iyz="0.0" />
        </inertial>
    </link>
    <!-- Back Wall -->
    <link name="back_wall">
        <collision>
            <origin rpy="0 0 0" xyz="0 0 0" />
            <geometry>
                <box size="0.1 1.6342 2.5" />
            </geometry>
        </collision>
        <inertial>
            <mass value="0.1" />
            <origin xyz="0 0 0" rpy="0 0 0" />
            <inertia ixx="0.03" iyy="0.03" izz="0.03" ixy="0.0" ixz="0.0" iyz="0.0" />
        </inertial>
    </link>
    <!-- Hut Wall -->
    <link name="hut_wall">
        <collision>
            <origin rpy="0 0 0" xyz="0 0 0" />
            <geometry>
                <box size="1.3292 0.1 2.5" />
            </geometry>
        </collision>
        <inertial>
            <mass value="0.1" />
            <origin xyz="0 0 0" rpy="0 0 0" />
            <inertia ixx="0.03" iyy="0.03" izz="0.03" ixy="0.0" ixz="0.0" iyz="0.0" />
        </inertial>
    </link>
    <!-- Counter Wall -->
    <link name="counter_wall">
        <collision>
            <origin rpy="0 0 0" xyz="0 0 0" />
            <geometry>
                <box size="1.3292 0.1 2.5" />
            </geometry>
        </collision>
        <inertial>
            <mass value="0.1" />
            <origin xyz="0 0 0" rpy="0 0 0" />
            <inertia ixx="0.03" iyy="0.03" izz="0.03" ixy="0.0" ixz="0.0" iyz="0.0" />
        </inertial>
    </link>
    <link name="newport_base">
        <inertial>
            <origin rpy="0 0 0" xyz="0 0 0" />
            <mass value="19.86735" />
            <inertia ixx="0" ixy="0" ixz="0" iyy="0" iyz="0" izz="0" />
        </inertial>
        <visual>
            <origin rpy="0 0 0" xyz="0 0 0" />
            <geometry>
                <mesh filename="package://oscar_description/meshes/newport/vh3660/visual/70k.dae" />
            </geometry>
            <material name="">
                <color rgba="0.79216 0.81961 0.93333 1" />
            </material>
        </visual>
        <collision>
            <origin rpy="0 0 0" xyz="0 0 0" />
            <geometry>
                <mesh filename="package://oscar_description/meshes/newport/vh3660/collision/bb12.stl" />
            </geometry>
        </collision>
    </link>
    <link name="newport_tabletop" />
    <joint name="newport_tabletop_joint" type="fixed">
        <!-- Taken from CAD in inches, converted to meters -->
        <origin rpy="0 0 0" xyz="0 0 0.1097661" />
        <parent link="newport_base" />
        <child link="newport_tabletop" />
    </joint>
    <link name="ur_mounting_plate_base">
        <inertial>
            <origin rpy="0 0 0" xyz="0 0 0" />
            <!-- Not measured -->
            <mass value="0.5" />
            <inertia ixx="0" ixy="0" ixz="0" iyy="0" iyz="0" izz="0" />
        </inertial>
        <visual>
            <origin rpy="0 0 0" xyz="0 0 0" />
            <geometry>
                <mesh filename="package://oscar_description/meshes/oscar/ur_big_mounting_plate/visual/171k.dae" />
            </geometry>
            <material name="">
                <color rgba="0.79216 0.81961 0.93333 1" />
            </material>
        </visual>
        <collision>
            <origin rpy="0 0 0" xyz="0 0 0" />
            <geometry>
                <mesh filename="package://oscar_description/meshes/oscar/ur_big_mounting_plate/collision/bb12.stl" />
            </geometry>
        </collision>
    </link>
    <link name="ur_mounting_plate_robotside" />
    <!-- Mean of multiple points of the surface -->
    <joint name="ur_mounting_plate_robotside_joint" type="fixed">
        <!-- <origin xyz="0 0 0.01309" rpy="0 0 0" /> -->
        <origin rpy="0 0 0" xyz="0 0 0.1651" />
        <parent link="ur_mounting_plate_base" />
        <child link="ur_mounting_plate_robotside" />
    </joint>
    <!--
    Base UR robot series xacro macro.

    NOTE: this is NOT a URDF. It cannot directly be loaded by consumers
    expecting a flattened '.urdf' file. See the top-level '.xacro' for that
    (but note: that .xacro must still be processed by the xacro command).

    For use in '.launch' files: use one of the 'load_urX.launch' convenience
    launch files.

    This file models the base kinematic chain of a UR robot, which then gets
    parameterised by various configuration files to convert it into a UR3(e),
    UR5(e), UR10(e) or UR16e.

    NOTE: the default kinematic parameters (ie: link lengths, frame locations,
    offets, etc) do not correspond to any particular robot. They are defaults
    only. There WILL be non-zero offsets between the Forward Kinematics results
    in TF (ie: robot_state_publisher) and the values reported by the Teach
    Pendant.

    For accurate (and robot-specific) transforms, the 'kinematics_parameters_file'
    parameter MUST point to a .yaml file containing the appropriate values for
    the targetted robot.

    If using the UniversalRobots/Universal_Robots_ROS_Driver, follow the steps
    described in the readme of that repository to extract the kinematic
    calibration from the controller and generate the required .yaml file.

    Main author of the migration to yaml configs: Ludovic Delval.

    Contributors to previous versions (in no particular order):

     - Felix Messmer
     - Kelsey Hawkins
     - Wim Meeussen
     - Shaun Edwards
     - Nadia Hammoudeh Garcia
     - Dave Hershberger
     - G. vd. Hoorn
     - Philip Long
     - Dave Coleman
     - Miguel Prada
     - Mathias Luedtke
     - Marcel Schnirring
     - Felix von Drigalski
     - Felix Exner
     - Jimmy Da Silva
     - Ajit Krisshna N L
     - Muhammad Asif Rana
  -->
    <!--
    NOTE: the macro defined in this file is NOT part of the public API of this
          package. Users CANNOT rely on this file being available, or stored in
          this location. Nor can they rely on the existence of the macro.
  -->
    <transmission name="ur_shoulder_pan_trans">
        <type>transmission_interface/SimpleTransmission</type>
        <joint name="ur_shoulder_pan_joint">
            <hardwareInterface>hardware_interface/PositionJointInterface</hardwareInterface>
        </joint>
        <actuator name="ur_shoulder_pan_motor">
            <mechanicalReduction>1</mechanicalReduction>
            <hardwareInterface>hardware_interface/EffortJointInterface</hardwareInterface>
        </actuator>
    </transmission>
    <transmission name="ur_shoulder_lift_trans">
        <type>transmission_interface/SimpleTransmission</type>
        <joint name="ur_shoulder_lift_joint">
            <hardwareInterface>hardware_interface/PositionJointInterface</hardwareInterface>
        </joint>
        <actuator name="ur_shoulder_lift_motor">
            <mechanicalReduction>1</mechanicalReduction>
            <hardwareInterface>hardware_interface/EffortJointInterface</hardwareInterface>
        </actuator>
    </transmission>
    <transmission name="ur_elbow_trans">
        <type>transmission_interface/SimpleTransmission</type>
        <joint name="ur_elbow_joint">
            <hardwareInterface>hardware_interface/PositionJointInterface</hardwareInterface>
        </joint>
        <actuator name="ur_elbow_motor">
            <mechanicalReduction>1</mechanicalReduction>
            <hardwareInterface>hardware_interface/EffortJointInterface</hardwareInterface>
        </actuator>
    </transmission>
    <transmission name="ur_wrist_1_trans">
        <type>transmission_interface/SimpleTransmission</type>
        <joint name="ur_wrist_1_joint">
            <hardwareInterface>hardware_interface/PositionJointInterface</hardwareInterface>
        </joint>
        <actuator name="ur_wrist_1_motor">
            <mechanicalReduction>1</mechanicalReduction>
            <hardwareInterface>hardware_interface/EffortJointInterface</hardwareInterface>
        </actuator>
    </transmission>
    <transmission name="ur_wrist_2_trans">
        <type>transmission_interface/SimpleTransmission</type>
        <joint name="ur_wrist_2_joint">
            <hardwareInterface>hardware_interface/PositionJointInterface</hardwareInterface>
        </joint>
        <actuator name="ur_wrist_2_motor">
            <mechanicalReduction>1</mechanicalReduction>
            <hardwareInterface>hardware_interface/EffortJointInterface</hardwareInterface>
        </actuator>
    </transmission>
    <transmission name="ur_wrist_3_trans">
        <type>transmission_interface/SimpleTransmission</type>
        <joint name="ur_wrist_3_joint">
            <hardwareInterface>hardware_interface/PositionJointInterface</hardwareInterface>
        </joint>
        <actuator name="ur_wrist_3_motor">
            <mechanicalReduction>1</mechanicalReduction>
            <hardwareInterface>hardware_interface/EffortJointInterface</hardwareInterface>
        </actuator>
    </transmission>
    <!-- links: main serial chain -->
    <link name="ur_base_link" />
    <link name="ur_base_link_inertia">
        <visual>
            <origin rpy="0 0 3.141592653589793" xyz="0 0 0" />
            <geometry>
                <mesh filename="package://ur_description/meshes/ur3/visual/base.dae" />
            </geometry>
            <material name="LightGrey">
                <color rgba="0.7 0.7 0.7 1.0" />
            </material>
        </visual>
        <collision>
            <origin rpy="0 0 3.141592653589793" xyz="0 0 0" />
            <geometry>
                <mesh filename="package://ur_description/meshes/ur3/collision/vhacd_h16/base.stl" />
            </geometry>
        </collision>
        <inertial>
            <mass value="2.0" />
            <origin rpy="0 0 0" xyz="0 0 0" />
            <inertia ixx="0.0030531654454" ixy="0.0" ixz="0.0" iyy="0.0030531654454" iyz="0.0" izz="0.005625" />
        </inertial>
    </link>
    <link name="ur_shoulder_link">
        <visual>
            <origin rpy="0 0 3.141592653589793" xyz="0 0 0" />
            <geometry>
                <mesh filename="package://ur_description/meshes/ur3/visual/shoulder.dae" />
            </geometry>
            <material name="LightGrey">
                <color rgba="0.7 0.7 0.7 1.0" />
            </material>
        </visual>
        <collision>
            <origin rpy="0 0 3.141592653589793" xyz="0 0 0" />
            <geometry>
                <mesh filename="package://ur_description/meshes/ur3/collision/vhacd_h16/shoulder.stl" />
            </geometry>
        </collision>
        <inertial>
            <mass value="2.0" />
            <origin rpy="0 0 0" xyz="0 0 0" />
            <inertia ixx="0.008093163429399999" ixy="0.0" ixz="0.0" iyy="0.008093163429399999" iyz="0.0" izz="0.005625" />
        </inertial>
    </link>
    <link name="ur_upper_arm_link">
        <visual>
            <origin rpy="1.5707963267948966 0 -1.5707963267948966" xyz="0 0 0.1198" />
            <geometry>
                <mesh filename="package://ur_description/meshes/ur3/visual/upperarm.dae" />
            </geometry>
            <material name="LightGrey">
                <color rgba="0.7 0.7 0.7 1.0" />
            </material>
        </visual>
        <collision>
            <origin rpy="1.5707963267948966 0 -1.5707963267948966" xyz="0 0 0.1198" />
            <geometry>
                <mesh filename="package://ur_description/meshes/ur3/collision/vhacd_h16/upperarm.stl" />
            </geometry>
        </collision>
        <inertial>
            <mass value="3.42" />
            <origin rpy="0 1.5707963267948966 0" xyz="-0.121825 0.0 0.12" />
            <inertia ixx="0.021728483221103233" ixy="0.0" ixz="0.0" iyy="0.021728483221103233" iyz="0.0" izz="0.00961875" />
        </inertial>
    </link>
    <link name="ur_forearm_link">
        <visual>
            <origin rpy="1.5707963267948966 0 -1.5707963267948966" xyz="0 0 0.0275" />
            <geometry>
                <mesh filename="package://ur_description/meshes/ur3/visual/forearm.dae" />
            </geometry>
            <material name="LightGrey">
                <color rgba="0.7 0.7 0.7 1.0" />
            </material>
        </visual>
        <collision>
            <origin rpy="1.5707963267948966 0 -1.5707963267948966" xyz="0 0 0.0275" />
            <geometry>
                <mesh filename="package://ur_description/meshes/ur3/collision/vhacd_h16/forearm.stl" />
            </geometry>
        </collision>
        <inertial>
            <mass value="1.26" />
            <origin rpy="0 1.5707963267948966 0" xyz="-0.106625 0.0 0.0275" />
            <inertia ixx="0.006546806443776375" ixy="0.0" ixz="0.0" iyy="0.006546806443776375" iyz="0.0" izz="0.00354375" />
        </inertial>
    </link>
    <link name="ur_wrist_1_link">
        <visual>
            <!-- TODO: Move this to a parameter -->
            <origin rpy="1.5707963267948966 0 0" xyz="0 0 -0.085" />
            <geometry>
                <mesh filename="package://ur_description/meshes/ur3/visual/wrist1.dae" />
            </geometry>
            <material name="LightGrey">
                <color rgba="0.7 0.7 0.7 1.0" />
            </material>
        </visual>
        <collision>
            <origin rpy="1.5707963267948966 0 0" xyz="0 0 -0.085" />
            <geometry>
                <mesh filename="package://ur_description/meshes/ur3/collision/vhacd_h16/wrist1.stl" />
            </geometry>
        </collision>
        <inertial>
            <mass value="0.8" />
            <origin rpy="0 0 0" xyz="0 0 0" />
            <inertia ixx="0.0016106408557434" ixy="0.0" ixz="0.0" iyy="0.0016106408557434" iyz="0.0" izz="0.00225" />
        </inertial>
    </link>
    <link name="ur_wrist_2_link">
        <visual>
            <origin rpy="0 0 0" xyz="0 0 -0.085" />
            <geometry>
                <mesh filename="package://ur_description/meshes/ur3/visual/wrist2.dae" />
            </geometry>
            <material name="LightGrey">
                <color rgba="0.7 0.7 0.7 1.0" />
            </material>
        </visual>
        <collision>
            <origin rpy="0 0 0" xyz="0 0 -0.085" />
            <geometry>
                <mesh filename="package://ur_description/meshes/ur3/collision/vhacd_h16/wrist2.stl" />
            </geometry>
        </collision>
        <inertial>
            <mass value="0.8" />
            <origin rpy="0 0 0" xyz="0 0 0" />
            <inertia ixx="0.0015721733711303997" ixy="0.0" ixz="0.0" iyy="0.0015721733711303997" iyz="0.0" izz="0.00225" />
        </inertial>
    </link>
    <link name="ur_wrist_3_link">
        <visual>
            <origin rpy="1.5707963267948966 0 0" xyz="0 0 -0.082" />
            <geometry>
                <mesh filename="package://ur_description/meshes/ur3/visual/wrist3.dae" />
            </geometry>
            <material name="LightGrey">
                <color rgba="0.7 0.7 0.7 1.0" />
            </material>
        </visual>
        <collision>
            <origin rpy="1.5707963267948966 0 0" xyz="0 0 -0.082" />
            <geometry>
                <mesh filename="package://ur_description/meshes/ur3/collision/vhacd_h16/wrist3.stl" />
            </geometry>
        </collision>
        <inertial>
            <mass value="0.35" />
            <origin rpy="0 0 0" xyz="0.0 0.0 -0.02" />
            <inertia ixx="0.00013626661215999998" ixy="0.0" ixz="0.0" iyy="0.00013626661215999998" iyz="0.0" izz="0.0001792" />
        </inertial>
    </link>
    <!-- joints: main serial chain -->
    <joint name="ur_base_link-base_link_inertia" type="fixed">
        <parent link="ur_base_link" />
        <child link="ur_base_link_inertia" />
        <!-- 'base_link' is REP-103 aligned (so X+ forward), while the internal
           frames of the robot/controller have X+ pointing backwards.
           Use the joint between 'base_link' and 'base_link_inertia' (a dummy
           link/frame) to introduce the necessary rotation over Z (of pi rad).
      -->
        <origin rpy="0 0 3.141592653589793" xyz="0 0 0" />
    </joint>
    <joint name="ur_shoulder_pan_joint" type="revolute">
        <parent link="ur_base_link_inertia" />
        <child link="ur_shoulder_link" />
        <origin rpy="0 0 2.788909693341134e-05" xyz="0 0 0.1519135963461435" />
        <axis xyz="0 0 1" />
        <limit effort="56.0" lower="-6.283185307179586" upper="6.283185307179586" velocity="3.141592653589793" />
        <dynamics damping="0" friction="0" />
    </joint>
    <joint name="ur_shoulder_lift_joint" type="revolute">
        <parent link="ur_shoulder_link" />
        <child link="ur_upper_arm_link" />
        <origin rpy="1.570842997539163 0 -3.478643464127787e-06" xyz="2.055946359576799e-05 0 0" />
        <axis xyz="0 0 1" />
        <limit effort="56.0" lower="-6.283185307179586" upper="6.283185307179586" velocity="3.141592653589793" />
        <dynamics damping="0" friction="0" />
    </joint>
    <joint name="ur_elbow_joint" type="revolute">
        <parent link="ur_upper_arm_link" />
        <child link="ur_forearm_link" />
        <origin rpy="0.0002419273107811124 -2.683708139035676e-05 -6.758303563369246e-05" xyz="-0.2436265756628402 0 0" />
        <axis xyz="0 0 1" />
        <limit effort="28.0" lower="-3.141592653589793" upper="3.141592653589793" velocity="3.141592653589793" />
        <dynamics damping="0" friction="0" />
    </joint>
    <joint name="ur_wrist_1_joint" type="revolute">
        <parent link="ur_forearm_link" />
        <child link="ur_wrist_1_link" />
        <origin rpy="0.00130948398496501 0.0001103072258368812 1.022363974326258e-05" xyz="-0.213196315637268 -0.0001470307749181737 0.1122813967685411" />
        <axis xyz="0 0 1" />
        <limit effort="12.0" lower="-6.283185307179586" upper="6.283185307179586" velocity="6.283185307179586" />
        <dynamics damping="0" friction="0" />
    </joint>
    <joint name="ur_wrist_2_joint" type="revolute">
        <parent link="ur_wrist_1_link" />
        <child link="ur_wrist_2_link" />
        <origin rpy="1.571343114660626 0 6.090906127424239e-05" xyz="-1.932285070751691e-05 -0.08536906110903648 -4.667877137511274e-05" />
        <axis xyz="0 0 1" />
        <limit effort="12.0" lower="-6.283185307179586" upper="6.283185307179586" velocity="6.283185307179586" />
        <dynamics damping="0" friction="0" />
    </joint>
    <joint name="ur_wrist_3_joint" type="revolute">
        <parent link="ur_wrist_2_link" />
        <child link="ur_wrist_3_link" />
        <origin rpy="1.569812093786671 3.141592653589793 3.141588684587207" xyz="1.737185017286329e-05 0.08237703035038596 -8.107821857099018e-05" />
        <axis xyz="0 0 1" />
        <limit effort="12.0" lower="-6.283185307179586" upper="6.283185307179586" velocity="6.283185307179586" />
        <dynamics damping="0" friction="0" />
    </joint>
    <!-- ROS-Industrial 'base' frame: base_link to UR 'Base' Coordinates transform -->
    <link name="ur_base" />
    <joint name="ur_base_link-base_fixed_joint" type="fixed">
        <!-- Note the rotation over Z of pi radians: as base_link is REP-103
           aligned (ie: has X+ forward, Y+ left and Z+ up), this is needed
           to correctly align 'base' with the 'Base' coordinate system of
           the UR controller.
      -->
        <origin rpy="0 0 3.141592653589793" xyz="0 0 0" />
        <parent link="ur_base_link" />
        <child link="ur_base" />
    </joint>
    <!-- ROS-Industrial 'flange' frame: attachment point for EEF models -->
    <link name="ur_flange" />
    <joint name="ur_wrist_3-flange" type="fixed">
        <parent link="ur_wrist_3_link" />
        <child link="ur_flange" />
        <origin rpy="0 -1.5707963267948966 -1.5707963267948966" xyz="0 0 0" />
    </joint>
    <!-- ROS-Industrial 'tool0' frame: all-zeros tool frame -->
    <link name="ur_tool0" />
    <joint name="ur_flange-tool0" type="fixed">
        <!-- default toolframe: X+ left, Y+ up, Z+ front -->
        <origin rpy="1.5707963267948966 0 1.5707963267948966" xyz="0 0 0" />
        <parent link="ur_flange" />
        <child link="ur_tool0" />
    </joint>
    <!--
    NOTE: the macros defined in this file are NOT part of the public API of this
          package. Users CANNOT rely on this file being available, or stored in
          this location. Nor can they rely on the existence of the two macros.

    Author: Ludovic Delval
    Contributor: Felix Messmer
  -->
    <!-- Link representing the FT-300 mounting plate for Universal Robots -->
    <link name="robotiq_ft300_coupling_robotside">
        <inertial>
            <origin rpy="0 0 0" xyz="0.00227643166121317 -0.00163641909670073 -0.000186465195632485" />
            <mass value="0.0212636185801172" />
            <inertia ixx="0" ixy="0" ixz="0" iyy="0" iyz="0" izz="0" />
        </inertial>
        <visual>
            <origin rpy="0 0 0" xyz="0 0 0" />
            <geometry>
                <mesh filename="package://robotiq_description/meshes/robotiq_fts_300_cpl_062/visual/fts_300_cpl_062.dae" />
            </geometry>
            <material name="">
                <color rgba="0.0392156862745098 0.0392156862745098 0.0392156862745098 1" />
            </material>
        </visual>
        <collision>
            <origin rpy="0 0 0" xyz="0 0 0" />
            <geometry>
                <mesh filename="package://robotiq_description/meshes/robotiq_fts_300_cpl_062/collision/bbox/fts_300_cpl_062.stl" />
            </geometry>
        </collision>
    </link>
    <link name="robotiq_ft300_coupling_toolside" />
    <joint name="robotiq_ft300_coupling_toolside_joint" type="fixed">
        <origin rpy="0 0 0" xyz="0.0027 0 0" />
        <parent link="robotiq_ft300_coupling_robotside" />
        <child link="robotiq_ft300_coupling_toolside" />
    </joint>
    <!--
    NOTE: the macros defined in this file are NOT part of the public API of this
          package. Users CANNOT rely on this file being available, or stored in
          this location. Nor can they rely on the existence of the two macros.

    Author: Ludovic Delval
    Contributor: Felix Messmer
  -->
    <link name="robotiq_ft300_robotside">
        <inertial>
            <origin rpy="0 0 0" xyz="0.01987 -0.00039088 -0.00013094" />
            <mass value="0.087805" />
            <inertia ixx="0" ixy="0" ixz="0" iyy="0" iyz="0" izz="0" />
        </inertial>
        <visual>
            <origin rpy="0 0 0" xyz="0 0 0" />
            <geometry>
                <mesh filename="package://robotiq_description/meshes/robotiq_ft_300/visual/ft_300.dae" />
            </geometry>
            <material name="">
                <color rgba="0.79216 0.81961 0.93333 1" />
            </material>
        </visual>
        <collision>
            <origin rpy="0 0 0" xyz="0 0 0" />
            <geometry>
                <mesh filename="package://robotiq_description/meshes/robotiq_ft_300/collision/bbox/ft_300.stl" />
            </geometry>
        </collision>
    </link>
    <!-- Make frame_id link as part of the kinematic change (e.g. for compatibility with cartesian force controllers) -->
    <link name="robotiq_ft300_frame_id" />
    <link name="robotiq_ft300_toolside" />
    <!-- FORCE REFERENCE FRAME
        As specified in the documentation:
        - The Z axis passes through the center of the depression with positive direction in the tool direction.
        - The X axis traces a symmetric line centered on the connector; the positive direction
            points the opposite way away from the connector.
        - The Y axis uses the right hand thumb rule according to X-Z. -->
    <joint name="robotiq_ft300_frame_id_joint" type="fixed">
        <origin rpy="-1.5707963267948966 0 -1.5707963267948966" xyz="0.0348 0 0" />
        <parent link="robotiq_ft300_robotside" />
        <child link="robotiq_ft300_frame_id" />
    </joint>
    <!-- Revert to ROS convention orientation -->
    <joint name="robotiq_ft300_toolside_joint" type="fixed">
        <origin rpy="0 -1.5707963267948966 1.5707963267948966" xyz="0 0 0" />
        <parent link="robotiq_ft300_frame_id" />
        <child link="robotiq_ft300_toolside" />
    </joint>
    <!--
    NOTE: the macros defined in this file are NOT part of the public API of this
          package. Users CANNOT rely on this file being available, or stored in
          this location. Nor can they rely on the existence of the two macros.

    Author: Ludovic Delval
    Contributor: Felix Messmer
  -->
    <link name="dual_gripper_coupling_robotside">
        <inertial>
            <!-- Computed from Solidworks, matches the Robotiq datasheet (2021/06/23) -->
            <origin rpy="0 0 0" xyz="0.01545 0 0" />
            <!-- From Robotiq datasheet (2021/06/23) -->
            <mass value="0.265" />
            <inertia ixx="0" ixy="0" ixz="0" iyy="0" iyz="0" izz="0" />
        </inertial>
        <visual>
            <origin rpy="0 0 0" xyz="0 0 0" />
            <geometry>
                <mesh filename="package://robotiq_description/meshes/robotiq_agc_apl_159_002/visual/agc_apl_159_002.dae" />
            </geometry>
            <material name="">
                <color rgba="0.792156862745098 0.819607843137255 0.933333333333333 1" />
            </material>
        </visual>
        <collision>
            <origin rpy="0 0 0" xyz="0 0 0" />
            <geometry>
                <mesh filename="package://robotiq_description/meshes/robotiq_agc_apl_159_002/collision/bbox/agc_apl_159_002.stl" />
            </geometry>
        </collision>
    </link>
    <link name="dual_gripper_coupling_toolside_left" />
    <link name="dual_gripper_coupling_toolside_right" />
    <joint name="dual_gripper_coupling_toolside_left_joint" type="fixed">
        <origin rpy="0 0 0.7853981633974483" xyz="0.027 0.043 0" />
        <parent link="dual_gripper_coupling_robotside" />
        <child link="dual_gripper_coupling_toolside_left" />
    </joint>
    <joint name="dual_gripper_coupling_toolside_right_joint" type="fixed">
        <origin rpy="0 0 -0.7853981633974483" xyz="0.027 -0.043 0" />
        <parent link="dual_gripper_coupling_robotside" />
        <child link="dual_gripper_coupling_toolside_right" />
    </joint>
    <link name="pipette_tcp" />
    <link name="camera_adapter_robotside">
        <inertial>
            <origin rpy="0 0 0" xyz="0 0 0" />
            <mass value="0.03" />
            <!--TODO check with 3d printer-->
            <inertia ixx="0" ixy="0" ixz="0" iyy="0" iyz="0" izz="0" />
        </inertial>
        <visual>
            <origin rpy="0 0 0" xyz="0 0 0" />
            <geometry>
                <mesh filename="package://oscar_description/meshes/picknik/ur5_realsense_camera_adapter/visual/28k.dae" />
            </geometry>
            <material name="">
                <color rgba="0.79216 0.81961 0.93333 1" />
            </material>
        </visual>
        <collision>
            <origin rpy="0 0 0" xyz="0 0 0" />
            <geometry>
                <mesh filename="package://oscar_description/meshes/picknik/ur5_realsense_camera_adapter/collision/p12.stl" />
            </geometry>
        </collision>
    </link>
    <link name="camera_adapter_toolside" />
    <link name="camera_adapter_camera" />
    <joint name="camera_adapter_toolside_joint" type="fixed">
        <origin rpy="0 0 0" xyz="0.007 0 0" />
        <parent link="camera_adapter_robotside" />
        <child link="camera_adapter_toolside" />
    </joint>
    <joint name="camera_adapter_camera_joint" type="fixed">
        <origin rpy="0 0.13962634015954636 0" xyz="0.00865 0 0.07977" />
        <parent link="camera_adapter_robotside" />
        <child link="camera_adapter_camera" />
    </joint>
    <!-- camera body, with origin at bottom screw mount -->
    <joint name="camera_joint" type="fixed">
        <origin rpy="0 0 0" xyz="0.010025 0 -0.0115" />
        <parent link="camera_adapter_camera" />
        <child link="camera_bottom_screw_frame" />
    </joint>
    <link name="camera_bottom_screw_frame" />
    <joint name="camera_link_joint" type="fixed">
        <origin rpy="0 0 0" xyz="0 0.02 0.0115" />
        <parent link="camera_bottom_screw_frame" />
        <child link="camera_link" />
    </joint>
    <link name="camera_link">
        <visual>
            <origin rpy="1.5707963267948966 0 1.5707963267948966" xyz="0.00987 -0.02 0" />
            <geometry>
                <mesh filename="package://realsense2_description/meshes/d415.stl" />
            </geometry>
            <material name="aluminum" />
        </visual>
        <collision>
            <origin rpy="0 0 0" xyz="0 -0.02 0" />
            <geometry>
                <box size="0.02005 0.099 0.023" />
            </geometry>
        </collision>
        <inertial>
            <mass value="0.072" />
            <!-- The following are not reliable values, and should not be used for modeling -->
            <origin xyz="0 0 0" rpy="0 0 0" />
            <inertia ixx="0.003881243" ixy="0.0" ixz="0.0" iyy="0.000498940" iyz="0.0" izz="0.003879257" />
        </inertial>
    </link>
    <joint name="camera_usb_plug_joint" type="fixed">
        <origin rpy="0 0 0" xyz="-0.005999999999999998 -0.0558 0" />
        <parent link="camera_link" />
        <child link="camera_usb_plug_link" />
    </joint>
    <link name="camera_usb_plug_link">
        <visual>
            <!-- 0.044850 0.008000 0.018500 -->
            <origin rpy="0 0 1.5707963267948966" xyz="0. -0.022425 0." />
            <geometry>
                <!--box size="0.044850 0.008 0.0185" /-->
                <mesh filename="package://realsense2_description/meshes/plug.stl" />
            </geometry>
            <material name="plastic" />
        </visual>
        <collision>
            <origin rpy="0 0 1.5707963267948966" xyz="0. -0.022425 0." />
            <geometry>
                <!--box size="0.044850 0.008 0.0185" /-->
                <mesh filename="package://realsense2_description/meshes/plug_collision.stl" />
            </geometry>
        </collision>
        <inertial>
            <mass value="0.1" />
            <origin xyz="0 0 0" rpy="0 0 0" />
            <inertia ixx="0.03" iyy="0.03" izz="0.03" ixy="0.0" ixz="0.0" iyz="0.0" />
        </inertial>
    </link>
    <link name="camera_color_optical_frame" />
    <!--
    NOTE: the macros defined in this file are NOT part of the public API of this
          package. Users CANNOT rely on this file being available, or stored in
          this location. Nor can they rely on the existence of the two macros.

    Author: Ludovic Delval
    Contributor: Felix Messmer
  -->
    <link name="robotiq_2f140_base_link">
        <inertial>
            <origin rpy="0 0 0" xyz="0.0349137712216298 -0.000307415638406242 -1.86112821823436E-05" />
            <mass value="0.124496292726075" />
            <inertia ixx="1.77198801578171E-05" ixy="-1.20168637369256E-06" ixz="-7.33154410139097E-08" iyy="6.51416874558209E-05" iyz="-3.67584779427649E-09" izz="4.97965327837907E-05" />
        </inertial>
        <visual>
            <origin rpy="0 0 0" xyz="0 0 0" />
            <geometry>
                <mesh filename="package://robotiq_description/meshes/robotiq_2f_140/visual/base.dae" />
            </geometry>
            <material name="">
                <color rgba="0.752941176470588 0.752941176470588 0.752941176470588 1" />
            </material>
        </visual>
        <collision>
            <origin rpy="0 0 0" xyz="0 0 0" />
            <geometry>
                <mesh filename="package://robotiq_description/meshes/robotiq_2f_140/collision/bbox/base.stl" />
            </geometry>
        </collision>
    </link>
    <link name="robotiq_2f140_left_outer_knuckle">
        <inertial>
            <origin rpy="0 0 0" xyz="0.000553430078305425 -0.0113324166394055 -2.069203532776E-08" />
            <mass value="0.00786620962275458" />
            <inertia ixx="0" ixy="0" ixz="0" iyy="0" iyz="0" izz="0" />
        </inertial>
        <visual>
            <origin rpy="0 0 0" xyz="0 0 0" />
            <geometry>
                <mesh filename="package://robotiq_description/meshes/robotiq_2f_140/visual/outer_knuckle.dae" />
            </geometry>
            <material name="">
                <color rgba="0.792156862745098 0.819607843137255 0.933333333333333 1" />
            </material>
        </visual>
        <collision>
            <origin rpy="0 0 0" xyz="0 0 0" />
            <geometry>
                <mesh filename="package://robotiq_description/meshes/robotiq_2f_140/collision/bbox/outer_knuckle.stl" />
            </geometry>
        </collision>
    </link>
    <link name="robotiq_2f140_left_outer_finger">
        <inertial>
            <origin rpy="0 0 0" xyz="0.037582513422451 -0.0147933878405319 1.75722175258395E-09" />
            <mass value="0.0164998179601088" />
            <inertia ixx="3.63881150640202E-07" ixy="7.77163079871056E-07" ixz="3.83932554975091E-15" iyy="1.72399139003576E-06" iyz="-6.12077326039638E-15" izz="2.0741644702864E-06" />
        </inertial>
        <visual>
            <origin rpy="0 0 0" xyz="0 0 0" />
            <geometry>
                <mesh filename="package://robotiq_description/meshes/robotiq_2f_140/visual/outer_finger.dae" />
            </geometry>
            <material name="">
                <color rgba="0.752941176470588 0.752941176470588 0.752941176470588 1" />
            </material>
        </visual>
        <collision>
            <origin rpy="0 0 0" xyz="0 0 0" />
            <geometry>
                <mesh filename="package://robotiq_description/meshes/robotiq_2f_140/collision/bbox/outer_finger.stl" />
            </geometry>
        </collision>
    </link>
    <link name="robotiq_2f140_left_inner_finger">
        <inertial>
            <origin rpy="0 0 0" xyz="0.0138261523043157 0.012041065004881 -2.07110001536426E-15" />
            <mass value="0.00728069074391804" />
            <inertia ixx="2.80233056217759E-09" ixy="-1.06385436552863E-08" ixz="-6.39274552405216E-21" iyy="5.288119896764E-08" iyz="-1.63868227162773E-21" izz="5.56835295298176E-08" />
        </inertial>
        <visual>
            <origin rpy="0 0 0" xyz="0 0 0" />
            <geometry>
                <mesh filename="package://robotiq_description/meshes/robotiq_2f_140/visual/inner_finger.dae" />
            </geometry>
            <material name="">
                <color rgba="0.752941176470588 0.752941176470588 0.752941176470588 1" />
            </material>
        </visual>
        <collision>
            <origin rpy="0 0 0" xyz="0 0 0" />
            <geometry>
                <mesh filename="package://robotiq_description/meshes/robotiq_2f_140/collision/bbox/inner_finger.stl" />
            </geometry>
        </collision>
    </link>
    <link name="robotiq_2f140_left_fingertip">
        <inertial>
            <origin rpy="0 0 0" xyz="-0.000109801182224895 0.00317755672771076 6.71012101645093E-17" />
            <mass value="0.0110245686419432" />
            <inertia ixx="2.08902759828054E-08" ixy="4.60038120722903E-10" ixz="1.38333794517888E-23" iyy="1.01307935181161E-11" iyz="-6.28172104669565E-22" izz="2.09004067763235E-08" />
        </inertial>
        <visual>
            <origin rpy="0 0 0" xyz="0 0 0" />
            <geometry>
                <mesh filename="package://robotiq_description/meshes/robotiq_2f_140/visual/fingertip.dae" />
            </geometry>
            <material name="">
                <color rgba="0.792156862745098 0.819607843137255 0.933333333333333 1" />
            </material>
        </visual>
        <collision>
            <origin rpy="0 0 0" xyz="0 0 0" />
            <geometry>
                <mesh filename="package://robotiq_description/meshes/robotiq_2f_140/collision/bbox/fingertip.stl" />
            </geometry>
        </collision>
    </link>
    <link name="robotiq_2f140_left_inner_knuckle">
        <inertial>
            <origin rpy="0 0 0" xyz="0.0361850676948983 -0.0331675189831137 -1.21207146841943E-08" />
            <mass value="0.0174460087279995" />
            <inertia ixx="1.15871030484505E-06" ixy="1.18962145386134E-06" ixz="-8.39568250113456E-14" iyy="1.41683380026142E-06" iyz="6.84207447322716E-14" izz="2.39357586071014E-06" />
        </inertial>
        <visual>
            <origin rpy="0 0 0" xyz="0 0 0" />
            <geometry>
                <mesh filename="package://robotiq_description/meshes/robotiq_2f_140/visual/inner_knuckle.dae" />
            </geometry>
            <material name="">
                <color rgba="0.752941176470588 0.752941176470588 0.752941176470588 1" />
            </material>
        </visual>
        <collision>
            <origin rpy="0 0 0" xyz="0 0 0" />
            <geometry>
                <mesh filename="package://robotiq_description/meshes/robotiq_2f_140/collision/bbox/inner_knuckle.stl" />
            </geometry>
        </collision>
    </link>
    <!--
    NOTE: the macros defined in this file are NOT part of the public API of this
          package. Users CANNOT rely on this file being available, or stored in
          this location. Nor can they rely on the existence of the two macros.

    Author: Ludovic Delval
    Contributor: Felix Messmer
  -->
    <!-- Link representing the silicon finger tip pad -->
    <link name="robotiq_2f140_left_fingertip_pad">
        <inertial>
            <origin rpy="0 0 0" xyz="0.00227643166121317 -0.00163641909670073 -0.000186465195632485" />
            <mass value="0.0212636185801172" />
            <inertia ixx="0" ixy="0" ixz="0" iyy="0" iyz="0" izz="0" />
        </inertial>
        <visual>
            <origin rpy="0 0 0" xyz="0 0 0" />
            <geometry>
                <mesh filename="package://robotiq_description/meshes/robotiq_agc_tip_220_140/visual/agc_tip_220_140.dae" />
            </geometry>
            <material name="">
                <color rgba="0.0392156862745098 0.0392156862745098 0.0392156862745098 1" />
            </material>
        </visual>
        <collision>
            <origin rpy="0 0 0" xyz="0 0 0" />
            <geometry>
                <mesh filename="package://robotiq_description/meshes/robotiq_agc_tip_220_140/collision/agc_tip_220_140.stl" />
            </geometry>
        </collision>
    </link>
    <link name="robotiq_2f140_right_outer_knuckle">
        <inertial>
            <origin rpy="0 0 0" xyz="0.000553430078305425 -0.0113324166394055 -2.069203532776E-08" />
            <mass value="0.00786620962275458" />
            <inertia ixx="0" ixy="0" ixz="0" iyy="0" iyz="0" izz="0" />
        </inertial>
        <visual>
            <origin rpy="0 0 0" xyz="0 0 0" />
            <geometry>
                <mesh filename="package://robotiq_description/meshes/robotiq_2f_140/visual/outer_knuckle.dae" />
            </geometry>
            <material name="">
                <color rgba="0.792156862745098 0.819607843137255 0.933333333333333 1" />
            </material>
        </visual>
        <collision>
            <origin rpy="0 0 0" xyz="0 0 0" />
            <geometry>
                <mesh filename="package://robotiq_description/meshes/robotiq_2f_140/collision/bbox/outer_knuckle.stl" />
            </geometry>
        </collision>
    </link>
    <link name="robotiq_2f140_right_outer_finger">
        <inertial>
            <origin rpy="0 0 0" xyz="0.037582513422451 -0.0147933878405319 1.75722175258395E-09" />
            <mass value="0.0164998179601088" />
            <inertia ixx="3.63881150640202E-07" ixy="7.77163079871056E-07" ixz="3.83932554975091E-15" iyy="1.72399139003576E-06" iyz="-6.12077326039638E-15" izz="2.0741644702864E-06" />
        </inertial>
        <visual>
            <origin rpy="0 0 0" xyz="0 0 0" />
            <geometry>
                <mesh filename="package://robotiq_description/meshes/robotiq_2f_140/visual/outer_finger.dae" />
            </geometry>
            <material name="">
                <color rgba="0.752941176470588 0.752941176470588 0.752941176470588 1" />
            </material>
        </visual>
        <collision>
            <origin rpy="0 0 0" xyz="0 0 0" />
            <geometry>
                <mesh filename="package://robotiq_description/meshes/robotiq_2f_140/collision/bbox/outer_finger.stl" />
            </geometry>
        </collision>
    </link>
    <link name="robotiq_2f140_right_inner_finger">
        <inertial>
            <origin rpy="0 0 0" xyz="0.0138261523043157 0.012041065004881 -2.07110001536426E-15" />
            <mass value="0.00728069074391804" />
            <inertia ixx="2.80233056217759E-09" ixy="-1.06385436552863E-08" ixz="-6.39274552405216E-21" iyy="5.288119896764E-08" iyz="-1.63868227162773E-21" izz="5.56835295298176E-08" />
        </inertial>
        <visual>
            <origin rpy="0 0 0" xyz="0 0 0" />
            <geometry>
                <mesh filename="package://robotiq_description/meshes/robotiq_2f_140/visual/inner_finger.dae" />
            </geometry>
            <material name="">
                <color rgba="0.752941176470588 0.752941176470588 0.752941176470588 1" />
            </material>
        </visual>
        <collision>
            <origin rpy="0 0 0" xyz="0 0 0" />
            <geometry>
                <mesh filename="package://robotiq_description/meshes/robotiq_2f_140/collision/bbox/inner_finger.stl" />
            </geometry>
        </collision>
    </link>
    <link name="robotiq_2f140_right_fingertip">
        <inertial>
            <origin rpy="0 0 0" xyz="-0.000109801182224895 0.00317755672771076 6.71012101645093E-17" />
            <mass value="0.0110245686419432" />
            <inertia ixx="2.08902759828054E-08" ixy="4.60038120722903E-10" ixz="1.38333794517888E-23" iyy="1.01307935181161E-11" iyz="-6.28172104669565E-22" izz="2.09004067763235E-08" />
        </inertial>
        <visual>
            <origin rpy="0 0 0" xyz="0 0 0" />
            <geometry>
                <mesh filename="package://robotiq_description/meshes/robotiq_2f_140/visual/fingertip.dae" />
            </geometry>
            <material name="">
                <color rgba="0.792156862745098 0.819607843137255 0.933333333333333 1" />
            </material>
        </visual>
        <collision>
            <origin rpy="0 0 0" xyz="0 0 0" />
            <geometry>
                <mesh filename="package://robotiq_description/meshes/robotiq_2f_140/collision/bbox/fingertip.stl" />
            </geometry>
        </collision>
    </link>
    <link name="robotiq_2f140_right_inner_knuckle">
        <inertial>
            <origin rpy="0 0 0" xyz="0.0361850676948983 -0.0331675189831137 -1.21207146841943E-08" />
            <mass value="0.0174460087279995" />
            <inertia ixx="1.15871030484505E-06" ixy="1.18962145386134E-06" ixz="-8.39568250113456E-14" iyy="1.41683380026142E-06" iyz="6.84207447322716E-14" izz="2.39357586071014E-06" />
        </inertial>
        <visual>
            <origin rpy="0 0 0" xyz="0 0 0" />
            <geometry>
                <mesh filename="package://robotiq_description/meshes/robotiq_2f_140/visual/inner_knuckle.dae" />
            </geometry>
            <material name="">
                <color rgba="0.752941176470588 0.752941176470588 0.752941176470588 1" />
            </material>
        </visual>
        <collision>
            <origin rpy="0 0 0" xyz="0 0 0" />
            <geometry>
                <mesh filename="package://robotiq_description/meshes/robotiq_2f_140/collision/bbox/inner_knuckle.stl" />
            </geometry>
        </collision>
    </link>
    <!--
    NOTE: the macros defined in this file are NOT part of the public API of this
          package. Users CANNOT rely on this file being available, or stored in
          this location. Nor can they rely on the existence of the two macros.

    Author: Ludovic Delval
    Contributor: Felix Messmer
  -->
    <!-- Link representing the silicon finger tip pad -->
    <link name="robotiq_2f140_right_fingertip_pad">
        <inertial>
            <origin rpy="0 0 0" xyz="0.00227643166121317 -0.00163641909670073 -0.000186465195632485" />
            <mass value="0.0212636185801172" />
            <inertia ixx="0" ixy="0" ixz="0" iyy="0" iyz="0" izz="0" />
        </inertial>
        <visual>
            <origin rpy="0 0 0" xyz="0 0 0" />
            <geometry>
                <mesh filename="package://robotiq_description/meshes/robotiq_agc_tip_220_140/visual/agc_tip_220_140.dae" />
            </geometry>
            <material name="">
                <color rgba="0.0392156862745098 0.0392156862745098 0.0392156862745098 1" />
            </material>
        </visual>
        <collision>
            <origin rpy="0 0 0" xyz="0 0 0" />
            <geometry>
                <mesh filename="package://robotiq_description/meshes/robotiq_agc_tip_220_140/collision/agc_tip_220_140.stl" />
            </geometry>
        </collision>
    </link>
    <link name="robotiq_2f140_tcp" />
    <joint name="robotiq_2f140_tcp_joint" type="fixed">
        <origin rpy="0 0 0" xyz="0.24127678495 0 0" />
        <parent link="robotiq_2f140_base_link" />
        <child link="robotiq_2f140_tcp" />
    </joint>
    <joint name="robotiq_2f140_left_outer_knuckle_joint" type="revolute">
        <origin rpy="0 3.141592653589793 3.141592653589793" xyz="0.062905 0.030601 0" />
        <parent link="robotiq_2f140_base_link" />
        <child link="robotiq_2f140_left_outer_knuckle" />
        <axis xyz="0 0 1" />
        <limit effort="176" lower="0" upper="0.792" velocity="2.0" />
    </joint>
    <joint name="robotiq_2f140_left_outer_finger_joint" type="fixed">
        <origin rpy="0 0 0" xyz="-0.0045554 -0.031421 0" />
        <parent link="robotiq_2f140_left_outer_knuckle" />
        <child link="robotiq_2f140_left_outer_finger" />
    </joint>
    <joint name="robotiq_2f140_left_inner_knuckle_joint" type="revolute">
        <origin rpy="0.0 0.0 0.0" xyz="0.06942 -0.0127 0" />
        <parent link="robotiq_2f140_base_link" />
        <child link="robotiq_2f140_left_inner_knuckle" />
        <axis xyz="0 0 1" />
        <limit effort="176" lower="-3.14" upper="3.14" velocity="2.0" />
        <mimic joint="robotiq_2f140_left_outer_knuckle_joint" multiplier="1" offset="0" />
    </joint>
    <joint name="robotiq_2f140_left_inner_finger_joint" type="revolute">
        <origin rpy="0 0 0" xyz="0.078873 -0.035489 0" />
        <parent link="robotiq_2f140_left_outer_finger" />
        <child link="robotiq_2f140_left_inner_finger" />
        <axis xyz="0 0 1" />
        <limit effort="176" lower="-3.14" upper="3.14" velocity="2.0" />
        <mimic joint="robotiq_2f140_left_outer_knuckle_joint" multiplier="-1" offset="0" />
    </joint>
    <joint name="robotiq_2f140_left_fingertip_joint" type="fixed">
        <origin rpy="0 0 0" xyz="0.046015 0.018901 0" />
        <parent link="robotiq_2f140_left_inner_finger" />
        <child link="robotiq_2f140_left_fingertip" />
    </joint>
    <joint name="robotiq_2f140_left_fingertip_pad_joint" type="fixed">
        <origin rpy="0 0 0" xyz="0 0.00476 0 " />
        <parent link="robotiq_2f140_left_fingertip" />
        <child link="robotiq_2f140_left_fingertip_pad" />
    </joint>
    <joint name="robotiq_2f140_right_outer_knuckle_joint" type="revolute">
        <origin rpy="0 0 0" xyz="0.062905 -0.030601 0" />
        <parent link="robotiq_2f140_base_link" />
        <child link="robotiq_2f140_right_outer_knuckle" />
        <axis xyz="0 0 1" />
        <limit effort="176" lower="-3.14" upper="3.14" velocity="2.0" />
        <mimic joint="robotiq_2f140_left_outer_knuckle_joint" multiplier="1" offset="0" />
    </joint>
    <joint name="robotiq_2f140_right_outer_finger_joint" type="fixed">
        <origin rpy="0 0 0" xyz="-0.0045554 -0.031421 0" />
        <parent link="robotiq_2f140_right_outer_knuckle" />
        <child link="robotiq_2f140_right_outer_finger" />
    </joint>
    <joint name="robotiq_2f140_right_inner_knuckle_joint" type="revolute">
        <origin rpy="-0.0 -3.141592653589793 -3.141592653589793" xyz="0.06942 0.0127 0" />
        <parent link="robotiq_2f140_base_link" />
        <child link="robotiq_2f140_right_inner_knuckle" />
        <axis xyz="0 0 1" />
        <limit effort="176" lower="-3.14" upper="3.14" velocity="2.0" />
        <mimic joint="robotiq_2f140_left_outer_knuckle_joint" multiplier="1" offset="0" />
    </joint>
    <joint name="robotiq_2f140_right_inner_finger_joint" type="revolute">
        <origin rpy="0 0 0" xyz="0.078873 -0.035489 0" />
        <parent link="robotiq_2f140_right_outer_finger" />
        <child link="robotiq_2f140_right_inner_finger" />
        <axis xyz="0 0 1" />
        <limit effort="176" lower="-3.14" upper="3.14" velocity="2.0" />
        <mimic joint="robotiq_2f140_left_outer_knuckle_joint" multiplier="-1" offset="0" />
    </joint>
    <joint name="robotiq_2f140_right_fingertip_joint" type="fixed">
        <origin rpy="0 0 0" xyz="0.046015 0.018901 0" />
        <parent link="robotiq_2f140_right_inner_finger" />
        <child link="robotiq_2f140_right_fingertip" />
    </joint>
    <joint name="robotiq_2f140_right_fingertip_pad_joint" type="fixed">
        <origin rpy="0 0 0" xyz="0 0.00476 0 " />
        <parent link="robotiq_2f140_right_fingertip" />
        <child link="robotiq_2f140_right_fingertip_pad" />
    </joint>
    <transmission name="robotiq_2f140_finger_joint_trans">
        <type>transmission_interface/SimpleTransmission</type>
        <joint name="robotiq_2f140_finger_joint">
            <hardwareInterface>PositionJointInterface</hardwareInterface>
        </joint>
        <actuator name="robotiq_2f140_finger_joint_motor">
            <mechanicalReduction>1</mechanicalReduction>
        </actuator>
    </transmission>
    <!-- TODO measure or calculate -->
    <link name="pipette_base">
        <inertial>
            <origin rpy="0 0 0" xyz="0 0 0" />
            <mass value="0.5" />
            <inertia ixx="0" ixy="0" ixz="0" iyy="0" iyz="0" izz="0" />
        </inertial>
        <visual>
            <origin rpy="0 0 0" xyz="0 0 0" />
            <geometry>
                <mesh filename="package://oscar_description/meshes/oscar/pipette_p200/visual/9k.dae" />
            </geometry>
            <material name="">
                <color rgba="0.79216 0.81961 0.93333 1" />
            </material>
        </visual>
        <collision>
            <origin rpy="0 0 0" xyz="0 0 0" />
            <geometry>
                <mesh filename="package://oscar_description/meshes/oscar/pipette_p200/collision/pipette_p200_coarse.stl" />
            </geometry>
        </collision>
    </link>
    <link name="pipette_tip" />
    <joint name="pipette_tip_joint" type="fixed">
        <!-- Original CAD -->
        <origin rpy="0 0 0" xyz="0.253442 0 0" />
        <parent link="pipette_base" />
        <child link="pipette_tip" />
    </joint>
    <joint name="newport_base_joint" type="fixed">
        <parent link="floor" />
        <child link="newport_base" />
        <!-- Offset by 1.5 inch for mounting foot height -->
        <origin rpy="0.0 0.0 0.0" xyz="-0.055 -0.0675 0.6604" />
    </joint>
    <joint name="back_wall_joint" type="fixed">
        <parent link="floor" />
        <child link="back_wall" />
        <origin rpy="0.0 0.0 0.0" xyz="0.6145999999999999 0 1.2373" />
    </joint>
    <joint name="hut_wall_joint" type="fixed">
        <parent link="floor" />
        <child link="hut_wall" />
        <origin rpy="0.0 0.0 0.0" xyz="0 0.7671 1.2373" />
    </joint>
    <joint name="counter_wall_joint" type="fixed">
        <parent link="floor" />
        <child link="counter_wall" />
        <origin rpy="0.0 0.0 0.0" xyz="0 -0.7671 1.2373" />
    </joint>
    <joint name="ur_mounting_plate_base_joint" type="fixed">
        <parent link="newport_tabletop" />
        <child link="ur_mounting_plate_base" />
        <!-- Newport tabletop has matrix of 1 inch hole gap-->
        <origin rpy="0.0 0.0 0.0" xyz="0.0 -0.0254  0.0" />
    </joint>
    <joint name="ur_base_joint" type="fixed">
        <parent link="ur_mounting_plate_robotside" />
        <child link="ur_base_link" />
        <origin rpy="0.0 0.0 1.5707963267948966" xyz="0.0 0.0 0.0" />
    </joint>
    <joint name="robotiq_fts300_coupling_joint" type="fixed">
        <parent link="ur_flange" />
        <child link="robotiq_ft300_coupling_robotside" />
        <!-- Align mounting plate to flange -->
        <origin rpy="3.141592653589793 0.0 0.0" xyz="0.0 0.0 0.0" />
    </joint>
    <joint name="robotiq_ft300_joint" type="fixed">
        <parent link="robotiq_ft300_coupling_toolside" />
        <child link="robotiq_ft300_robotside" />
        <origin rpy="0 0.0 0.0" xyz="0.0 0.0 0.0" />
    </joint>
    <joint name="dual_gripper_coupling_robotside_joint" type="fixed">
        <parent link="robotiq_ft300_toolside" />
        <child link="dual_gripper_coupling_robotside" />
        <origin rpy="0.0 0.0 0.0" xyz="0.0 0.0 0.0" />
    </joint>
    <joint name="camera_adapter_robotside_joint" type="fixed">
        <parent link="dual_gripper_coupling_toolside_left" />
        <child link="camera_adapter_robotside" />
        <origin rpy="0 0 0" xyz="0 0 0" />
    </joint>
    <joint name="robotiq_2f140_base_joint" type="fixed">
        <parent link="camera_adapter_toolside" />
        <child link="robotiq_2f140_base_link" />
        <!-- <origin xyz="0.0 0.0 0.0" rpy="0 0 0" /> -->
        <origin rpy="0 0 0" xyz="0.00160516037 0.00101565847 -0.00215532428" />
    </joint>
    <!-- Calibrated with moveit_calibration pkg -->
    <!-- Error: 0.0021 m, 0.0063 rad-->
    <joint name="camera_color_optical_frame_joint" type="fixed">
        <parent link="ur_wrist_3_link" />
        <child link="camera_color_optical_frame" />
        <origin rpy="-0.1188682 -0.7931895 -0.0029631" xyz="-0.0852237 -0.0776651 0.0608126" />
    </joint>
    <!-- <joint name="robotiq_2f140_base_joint" type="fixed"> -->
    <!--   <parent link= "dual_gripper_coupling_toolside_left" /> -->
    <!--   <child link = "robotiq_2f140_base_link" /> -->
    <!--   <!-\- <origin xyz="0.0 0.0 0.0" rpy="0 0 0" /> -\-> -->
    <!--   <origin xyz="${tcp_calibration_gripper}" rpy="0 0 0" /> -->
    <!-- </joint> -->
    <link name="robotiq_2f140_tcp_cad" />
    <joint name="robotiq_2f140_tcp_cad_joint" type="fixed">
        <parent link="dual_gripper_coupling_toolside_left" />
        <child link="robotiq_2f140_tcp_cad" />
        <origin rpy="0 0 0" xyz="0.24127678495 0 0" />
    </joint>
    <joint name="pipette_base_joint" type="fixed">
        <parent link="dual_gripper_coupling_toolside_right" />
        <child link="pipette_base" />
        <origin rpy="3.141592653589793 0.0 0.0" xyz="0.0 0.0 0.0" />
    </joint>
    <!-- Sanity Check -->
    <!-- <link name="pipette_tcp_test"/> -->
    <!-- <joint name="lol" type="fixed"> -->
    <!--   <parent link= "ur_tool0" /> -->
    <!--   <child link = "pipette_tcp_test" /> -->
    <!--   <origin xyz="0.223439 -0.00046209 0.243363" rpy="0.0 0.0 0.0" /> -->
    <!-- </joint> -->
    <!-- Conveniance frame -->
    <joint name="pipette_tcp_joint" type="fixed">
        <parent link="pipette_tip" />
        <child link="pipette_tcp" />
        <!-- Calibrated on Apr 18 2024 with Tool Point Calibration ROS package -->
        <!-- Calibration captured 4 tool poses (out of 4 requested). Computing calibration... -->
        <!-- Calibrated tcp (meters in xyz): [   0.223439 -0.00046209    0.243363] from ur_tool0 -->
        <!-- Touch point (meters in xyz): [-0.240945  0.241088 0.0427421] in frame newport_tabletop -->
        <!-- Average residual: 1.43073e-07 -->
        <!-- <origin xyz="0.0006228806938889386 0.0011144002871499858 -0.00046208999999987344" rpy="0.0 0.0 0.0" /> -->
        <origin rpy="3.141592653589793 0.0 0.0" xyz="0.0006464523002427391 0.0005510077330404747 -0.0007046087554606569" />
    </joint>
    <transmission name="trans_robotiq_2f140_left_outer_knuckle_joint">
        <type>transmission_interface/SimpleTransmission</type>
        <joint name="robotiq_2f140_left_outer_knuckle_joint">
            <hardwareInterface>hardware_interface/EffortJointInterface</hardwareInterface>
        </joint>
        <actuator name="robotiq_2f140_left_outer_knuckle_joint_motor">
            <hardwareInterface>hardware_interface/EffortJointInterface</hardwareInterface>
            <mechanicalReduction>1</mechanicalReduction>
        </actuator>
    </transmission>
    <transmission name="trans_robotiq_2f140_left_inner_knuckle_joint">
        <type>transmission_interface/SimpleTransmission</type>
        <joint name="robotiq_2f140_left_inner_knuckle_joint">
            <hardwareInterface>hardware_interface/EffortJointInterface</hardwareInterface>
        </joint>
        <actuator name="robotiq_2f140_left_inner_knuckle_joint_motor">
            <hardwareInterface>hardware_interface/EffortJointInterface</hardwareInterface>
            <mechanicalReduction>1</mechanicalReduction>
        </actuator>
    </transmission>
    <transmission name="trans_robotiq_2f140_left_inner_finger_joint">
        <type>transmission_interface/SimpleTransmission</type>
        <joint name="robotiq_2f140_left_inner_finger_joint">
            <hardwareInterface>hardware_interface/EffortJointInterface</hardwareInterface>
        </joint>
        <actuator name="robotiq_2f140_left_inner_finger_joint_motor">
            <hardwareInterface>hardware_interface/EffortJointInterface</hardwareInterface>
            <mechanicalReduction>1</mechanicalReduction>
        </actuator>
    </transmission>
    <transmission name="trans_robotiq_2f140_right_outer_knuckle_joint">
        <type>transmission_interface/SimpleTransmission</type>
        <joint name="robotiq_2f140_right_outer_knuckle_joint">
            <hardwareInterface>hardware_interface/EffortJointInterface</hardwareInterface>
        </joint>
        <actuator name="robotiq_2f140_right_outer_knuckle_joint_motor">
            <hardwareInterface>hardware_interface/EffortJointInterface</hardwareInterface>
            <mechanicalReduction>1</mechanicalReduction>
        </actuator>
    </transmission>
    <transmission name="trans_robotiq_2f140_right_inner_knuckle_joint">
        <type>transmission_interface/SimpleTransmission</type>
        <joint name="robotiq_2f140_right_inner_knuckle_joint">
            <hardwareInterface>hardware_interface/EffortJointInterface</hardwareInterface>
        </joint>
        <actuator name="robotiq_2f140_right_inner_knuckle_joint_motor">
            <hardwareInterface>hardware_interface/EffortJointInterface</hardwareInterface>
            <mechanicalReduction>1</mechanicalReduction>
        </actuator>
    </transmission>
    <transmission name="trans_robotiq_2f140_right_inner_finger_joint">
        <type>transmission_interface/SimpleTransmission</type>
        <joint name="robotiq_2f140_right_inner_finger_joint">
            <hardwareInterface>hardware_interface/EffortJointInterface</hardwareInterface>
        </joint>
        <actuator name="robotiq_2f140_right_inner_finger_joint_motor">
            <hardwareInterface>hardware_interface/EffortJointInterface</hardwareInterface>
            <mechanicalReduction>1</mechanicalReduction>
        </actuator>
    </transmission>
    <gazebo>
        <plugin name="gazebo_ros_control" filename="libgazebo_ros_control.so">
            <robotNamespace>/</robotNamespace>
        </plugin>
    </gazebo>
</robot>
