<?xml version="1.0" ?>
<!-- =================================================================================== -->
<!-- |    This document was autogenerated by xacro from /home/captain-yoshi/ws/ros/oscar_ws/src/oscar_robot_setup/oscar_robot_setup_description/urdf/oscar_panda_lab3023.xacro | -->
<!-- |    EDITING THIS FILE BY HAND IS NOT RECOMMENDED                                 | -->
<!-- =================================================================================== -->
<robot name="oscar_panda_lab3023">
    <material name="aluminum">
        <color rgba="0.5 0.5 0.5 1" />
    </material>
    <material name="plastic">
        <color rgba="0.1 0.1 0.1 1" />
    </material>
    <!-- TCP calibration of the robotiq gripper (xyz)-->
    <!-- <xacro:property name="tcp_calibration_gripper" value="0.0010977079105917165 -0.00047849967130053628 -2.3860966923898729e-05" /> -->
    <!-- Floor -->
    <link name="floor">
        <collision>
            <origin rpy="0 0 0" xyz="0 0 0" />
            <geometry>
                <box size="1.3292 1.6342 0.0254" />
            </geometry>
        </collision>
        <inertial>
            <mass value="0.1" />
            <origin xyz="0 0 0" rpy="0 0 0" />
            <inertia ixx="0.03" iyy="0.03" izz="0.03" ixy="0.0" ixz="0.0" iyz="0.0" />
        </inertial>
    </link>
    <!-- Back Wall -->
    <link name="back_wall">
        <collision>
            <origin rpy="0 0 0" xyz="0 0 0" />
            <geometry>
                <box size="0.1 1.6342 2.5" />
            </geometry>
        </collision>
        <inertial>
            <mass value="0.1" />
            <origin xyz="0 0 0" rpy="0 0 0" />
            <inertia ixx="0.03" iyy="0.03" izz="0.03" ixy="0.0" ixz="0.0" iyz="0.0" />
        </inertial>
    </link>
    <!-- Hut Wall -->
    <link name="hut_wall">
        <collision>
            <origin rpy="0 0 0" xyz="0 0 0" />
            <geometry>
                <box size="1.3292 0.1 2.5" />
            </geometry>
        </collision>
        <inertial>
            <mass value="0.1" />
            <origin xyz="0 0 0" rpy="0 0 0" />
            <inertia ixx="0.03" iyy="0.03" izz="0.03" ixy="0.0" ixz="0.0" iyz="0.0" />
        </inertial>
    </link>
    <!-- Counter Wall -->
    <link name="counter_wall">
        <collision>
            <origin rpy="0 0 0" xyz="0 0 0" />
            <geometry>
                <box size="1.3292 0.1 2.5" />
            </geometry>
        </collision>
        <inertial>
            <mass value="0.1" />
            <origin xyz="0 0 0" rpy="0 0 0" />
            <inertia ixx="0.03" iyy="0.03" izz="0.03" ixy="0.0" ixz="0.0" iyz="0.0" />
        </inertial>
    </link>
    <link name="newport_base">
        <inertial>
            <origin rpy="0 0 0" xyz="0 0 0" />
            <mass value="19.86735" />
            <inertia ixx="0" ixy="0" ixz="0" iyy="0" iyz="0" izz="0" />
        </inertial>
        <visual>
            <origin rpy="0 0 0" xyz="0 0 0" />
            <geometry>
                <mesh filename="package://oscar_description/meshes/newport/vh3660/visual/82k.dae" />
            </geometry>
            <material name="">
                <color rgba="0.79216 0.81961 0.93333 1" />
            </material>
        </visual>
        <collision>
            <origin rpy="0 0 0" xyz="0 0 0" />
            <geometry>
                <mesh filename="package://oscar_description/meshes/newport/vh3660/collision/bb12.stl" />
            </geometry>
        </collision>
    </link>
    <link name="newport_tabletop" />
    <joint name="newport_tabletop_joint" type="fixed">
        <!-- Taken from CAD in inches, converted to meters -->
        <origin rpy="0 0 0" xyz="0 0 0.1097661" />
        <parent link="newport_base" />
        <child link="newport_tabletop" />
    </joint>
    <link name="panda_link0">
        <visual>
            <geometry>
                <mesh filename="file:///home/captain-yoshi/ws/ros/oscar_ws/src/moveit_resources/panda_description/meshes/visual/link0.dae" />
            </geometry>
        </visual>
        <collision>
            <geometry>
                <mesh filename="file:///home/captain-yoshi/ws/ros/oscar_ws/src/moveit_resources/panda_description/meshes/collision/link0.stl" />
            </geometry>
        </collision>
        <inertial>
            <origin rpy="0 0 0" xyz="-0.041018 -0.00014 0.049974" />
            <mass value="0.629769" />
            <inertia ixx="0.00315" ixy="8.2904E-7" ixz="0.00015" iyy="0.00388" iyz="8.2299E-6" izz="0.004285" />
        </inertial>
    </link>
    <link name="panda_link1">
        <visual>
            <geometry>
                <mesh filename="file:///home/captain-yoshi/ws/ros/oscar_ws/src/moveit_resources/panda_description/meshes/visual/link1.dae" />
            </geometry>
        </visual>
        <collision>
            <geometry>
                <mesh filename="file:///home/captain-yoshi/ws/ros/oscar_ws/src/moveit_resources/panda_description/meshes/collision/link1.stl" />
            </geometry>
        </collision>
        <inertial>
            <origin rpy="0 0 0" xyz="0.003875 0.002081 -0.04762" />
            <mass value="4.970684" />
            <inertia ixx="0.70337" ixy="-0.000139" ixz="0.006772" iyy="0.70661" iyz="0.019169" izz="0.009117" />
        </inertial>
    </link>
    <joint name="panda_joint1" type="revolute">
        <safety_controller k_position="100.0" k_velocity="40.0" soft_lower_limit="-2.8973" soft_upper_limit="2.8973" />
        <origin rpy="0 0 0" xyz="0 0 0.333" />
        <parent link="panda_link0" />
        <child link="panda_link1" />
        <axis xyz="0 0 1" />
        <limit effort="87" lower="-2.9671" upper="2.9671" velocity="2.3925" />
        <dynamics D="1" K="7000" damping="0.003" friction="0.0" mu_coulomb="0" mu_viscous="16" />
    </joint>
    <link name="panda_link2">
        <visual>
            <geometry>
                <mesh filename="file:///home/captain-yoshi/ws/ros/oscar_ws/src/moveit_resources/panda_description/meshes/visual/link2.dae" />
            </geometry>
        </visual>
        <collision>
            <geometry>
                <mesh filename="file:///home/captain-yoshi/ws/ros/oscar_ws/src/moveit_resources/panda_description/meshes/collision/link2.stl" />
            </geometry>
        </collision>
        <inertial>
            <origin rpy="0 0 0" xyz="-0.003141 -0.02872  0.003495" />
            <mass value="0.646926" />
            <inertia ixx="0.007962" ixy="-3.925E-3" ixz="1.0254E-2" iyy="2.811E-2" iyz="7.04E-4" izz="2.5995E-2" />
        </inertial>
    </link>
    <joint name="panda_joint2" type="revolute">
        <safety_controller k_position="100.0" k_velocity="40.0" soft_lower_limit="-1.7628" soft_upper_limit="1.7628" />
        <origin rpy="-1.57079632679 0 0" xyz="0 0 0" />
        <parent link="panda_link1" />
        <child link="panda_link2" />
        <axis xyz="0 0 1" />
        <limit effort="87" lower="-1.8326" upper="1.8326" velocity="2.3925" />
        <dynamics D="1" K="7000" damping="0.003" friction="0.0" mu_coulomb="0" mu_viscous="16" />
    </joint>
    <link name="panda_link3">
        <visual>
            <geometry>
                <mesh filename="file:///home/captain-yoshi/ws/ros/oscar_ws/src/moveit_resources/panda_description/meshes/visual/link3.dae" />
            </geometry>
        </visual>
        <collision>
            <geometry>
                <mesh filename="file:///home/captain-yoshi/ws/ros/oscar_ws/src/moveit_resources/panda_description/meshes/collision/link3.stl" />
            </geometry>
        </collision>
        <inertial>
            <origin rpy="0 0 0" xyz="2.7518E-2 3.9252E-2 -6.6502E-2" />
            <mass value="3.228604" />
            <inertia ixx="3.7242E-2" ixy="-4.761E-3" ixz="-1.1396E-2" iyy="3.6155E-2" iyz="-1.2805E-2" izz="1.083E-2" />
        </inertial>
    </link>
    <joint name="panda_joint3" type="revolute">
        <safety_controller k_position="100.0" k_velocity="40.0" soft_lower_limit="-2.8973" soft_upper_limit="2.8973" />
        <origin rpy="1.57079632679 0 0" xyz="0 -0.316 0" />
        <parent link="panda_link2" />
        <child link="panda_link3" />
        <axis xyz="0 0 1" />
        <limit effort="87" lower="-2.9671" upper="2.9671" velocity="2.3925" />
        <dynamics D="1" K="7000" damping="0.003" friction="0.0" mu_coulomb="0" mu_viscous="16" />
    </joint>
    <link name="panda_link4">
        <visual>
            <geometry>
                <mesh filename="file:///home/captain-yoshi/ws/ros/oscar_ws/src/moveit_resources/panda_description/meshes/visual/link4.dae" />
            </geometry>
        </visual>
        <collision>
            <geometry>
                <mesh filename="file:///home/captain-yoshi/ws/ros/oscar_ws/src/moveit_resources/panda_description/meshes/collision/link4.stl" />
            </geometry>
        </collision>
        <inertial>
            <origin rpy="0 0 0" xyz="-5.317E-2 1.04419E-1 2.7454E-2" />
            <mass value="3.587895" />
            <inertia ixx="2.5853E-2" ixy="7.796E-3" ixz="-1.332E-3" iyy="1.9552E-2" iyz="8.641E-3" izz="2.8323E-2" />
        </inertial>
    </link>
    <joint name="panda_joint4" type="revolute">
        <safety_controller k_position="100.0" k_velocity="40.0" soft_lower_limit="-3.0718" soft_upper_limit="0.0175" />
        <origin rpy="1.57079632679 0 0" xyz="0.0825 0 0" />
        <parent link="panda_link3" />
        <child link="panda_link4" />
        <axis xyz="0 0 1" />
        <limit effort="87" lower="-3.1416" upper="0.0873" velocity="2.3925" />
        <dynamics D="1" K="7000" damping="0.003" friction="0.0" mu_coulomb="0" mu_viscous="16" />
    </joint>
    <link name="panda_link5">
        <visual>
            <geometry>
                <mesh filename="file:///home/captain-yoshi/ws/ros/oscar_ws/src/moveit_resources/panda_description/meshes/visual/link5.dae" />
            </geometry>
        </visual>
        <collision>
            <geometry>
                <mesh filename="file:///home/captain-yoshi/ws/ros/oscar_ws/src/moveit_resources/panda_description/meshes/collision/link5.stl" />
            </geometry>
        </collision>
        <inertial>
            <origin rpy="0 0 0" xyz="-1.1953E-2 4.1065E-2 -3.8437E-2" />
            <mass value="1.225946" />
            <inertia ixx="3.5549E-2" ixy="-2.117E-3" ixz="-4.037E-3" iyy="2.9474E-2" iyz="2.29E-4" izz="8.627E-3" />
        </inertial>
    </link>
    <joint name="panda_joint5" type="revolute">
        <safety_controller k_position="100.0" k_velocity="40.0" soft_lower_limit="-2.8973" soft_upper_limit="2.8973" />
        <origin rpy="-1.57079632679 0 0" xyz="-0.0825 0.384 0" />
        <parent link="panda_link4" />
        <child link="panda_link5" />
        <axis xyz="0 0 1" />
        <limit effort="12" lower="-2.9671" upper="2.9671" velocity="2.8710" />
        <dynamics D="1" K="7000" damping="0.003" friction="0.0" mu_coulomb="0" mu_viscous="16" />
    </joint>
    <link name="panda_link6">
        <visual>
            <geometry>
                <mesh filename="file:///home/captain-yoshi/ws/ros/oscar_ws/src/moveit_resources/panda_description/meshes/visual/link6.dae" />
            </geometry>
        </visual>
        <collision>
            <geometry>
                <mesh filename="file:///home/captain-yoshi/ws/ros/oscar_ws/src/moveit_resources/panda_description/meshes/collision/link6.stl" />
            </geometry>
        </collision>
        <inertial>
            <origin rpy="0 0 0" xyz="6.0149E-2 -1.4117E-2 -1.0517E-2" />
            <mass value="1.666555" />
            <inertia ixx="1.964E-3" ixy="1.09E-4" ixz="-1.158E-3" iyy="4.354E-3" iyz="3.41E-4" izz="5.433E-3" />
        </inertial>
    </link>
    <joint name="panda_joint6" type="revolute">
        <safety_controller k_position="100.0" k_velocity="40.0" soft_lower_limit="-0.0175" soft_upper_limit="3.7525" />
        <origin rpy="1.57079632679 0 0" xyz="0 0 0" />
        <parent link="panda_link5" />
        <child link="panda_link6" />
        <axis xyz="0 0 1" />
        <limit effort="12" lower="-0.0873" upper="3.8223" velocity="2.8710" />
        <dynamics D="1" K="7000" damping="0.003" friction="0.0" mu_coulomb="0" mu_viscous="16" />
    </joint>
    <link name="panda_link7">
        <visual>
            <geometry>
                <mesh filename="file:///home/captain-yoshi/ws/ros/oscar_ws/src/moveit_resources/panda_description/meshes/visual/link7.dae" />
            </geometry>
        </visual>
        <collision>
            <geometry>
                <mesh filename="file:///home/captain-yoshi/ws/ros/oscar_ws/src/moveit_resources/panda_description/meshes/collision/link7.stl" />
            </geometry>
        </collision>
        <inertial>
            <origin rpy="0 0 0" xyz="1.0517E-2 -4.252E-3 6.1597E-2" />
            <mass value="7.35522E-1" />
            <inertia ixx="1.2516E-2" ixy="-4.28E-4" ixz="-1.19E-3" iyy="1.0027E-2" iyz="-7.41E-4" izz="4.815E-3" />
        </inertial>
    </link>
    <joint name="panda_joint7" type="revolute">
        <safety_controller k_position="100.0" k_velocity="40.0" soft_lower_limit="-2.8973" soft_upper_limit="2.8973" />
        <origin rpy="1.57079632679 0 0" xyz="0.088 0 0" />
        <parent link="panda_link6" />
        <child link="panda_link7" />
        <axis xyz="0 0 1" />
        <limit effort="12" lower="-2.9671" upper="2.9671" velocity="2.8710" />
        <dynamics D="1" K="7000" damping="0.003" friction="0.0" mu_coulomb="0" mu_viscous="16" />
    </joint>
    <link name="panda_link8" />
    <joint name="panda_joint8" type="fixed">
        <origin rpy="0 0 0" xyz="0 0 0.107" />
        <parent link="panda_link7" />
        <child link="panda_link8" />
        <axis xyz="0 0 0" />
    </joint>
    <!--
    NOTE: the macros defined in this file are NOT part of the public API of this
          package. Users CANNOT rely on this file being available, or stored in
          this location. Nor can they rely on the existence of the two macros.

    Author: Ludovic Delval
    Contributor: Felix Messmer
  -->
    <!-- Link representing the FT-300 mounting plate for Universal Robots -->
    <link name="robotiq_ft300_coupling_robotside">
        <inertial>
            <origin rpy="0 0 0" xyz="0.00227643166121317 -0.00163641909670073 -0.000186465195632485" />
            <mass value="0.0212636185801172" />
            <inertia ixx="0" ixy="0" ixz="0" iyy="0" iyz="0" izz="0" />
        </inertial>
        <visual>
            <origin rpy="0 0 0" xyz="0 0 0" />
            <geometry>
                <mesh filename="package://robotiq_description/meshes/robotiq_fts_300_cpl_062/visual/fts_300_cpl_062.dae" />
            </geometry>
            <material name="">
                <color rgba="0.0392156862745098 0.0392156862745098 0.0392156862745098 1" />
            </material>
        </visual>
        <collision>
            <origin rpy="0 0 0" xyz="0 0 0" />
            <geometry>
                <mesh filename="package://robotiq_description/meshes/robotiq_fts_300_cpl_062/collision/bbox/fts_300_cpl_062.stl" />
            </geometry>
        </collision>
    </link>
    <link name="robotiq_ft300_coupling_toolside" />
    <joint name="robotiq_ft300_coupling_toolside_joint" type="fixed">
        <origin rpy="0 0 0" xyz="0.0027 0 0" />
        <parent link="robotiq_ft300_coupling_robotside" />
        <child link="robotiq_ft300_coupling_toolside" />
    </joint>
    <!--
    NOTE: the macros defined in this file are NOT part of the public API of this
          package. Users CANNOT rely on this file being available, or stored in
          this location. Nor can they rely on the existence of the two macros.

    Author: Ludovic Delval
    Contributor: Felix Messmer
  -->
    <link name="robotiq_ft300_robotside">
        <inertial>
            <origin rpy="0 0 0" xyz="0.01987 -0.00039088 -0.00013094" />
            <mass value="0.087805" />
            <inertia ixx="0" ixy="0" ixz="0" iyy="0" iyz="0" izz="0" />
        </inertial>
        <visual>
            <origin rpy="0 0 0" xyz="0 0 0" />
            <geometry>
                <mesh filename="package://robotiq_description/meshes/robotiq_ft_300/visual/ft_300.dae" />
            </geometry>
            <material name="">
                <color rgba="0.79216 0.81961 0.93333 1" />
            </material>
        </visual>
        <collision>
            <origin rpy="0 0 0" xyz="0 0 0" />
            <geometry>
                <mesh filename="package://robotiq_description/meshes/robotiq_ft_300/collision/bbox/ft_300.stl" />
            </geometry>
        </collision>
    </link>
    <!-- Make frame_id link as part of the kinematic change (e.g. for compatibility with cartesian force controllers) -->
    <link name="robotiq_ft300_frame_id" />
    <link name="robotiq_ft300_toolside" />
    <!-- FORCE REFERENCE FRAME
        As specified in the documentation:
        - The Z axis passes through the center of the depression with positive direction in the tool direction.
        - The X axis traces a symmetric line centered on the connector; the positive direction
            points the opposite way away from the connector.
        - The Y axis uses the right hand thumb rule according to X-Z. -->
    <joint name="robotiq_ft300_frame_id_joint" type="fixed">
        <origin rpy="-1.5707963267948966 0 -1.5707963267948966" xyz="0.0348 0 0" />
        <parent link="robotiq_ft300_robotside" />
        <child link="robotiq_ft300_frame_id" />
    </joint>
    <!-- Revert to ROS convention orientation -->
    <joint name="robotiq_ft300_toolside_joint" type="fixed">
        <origin rpy="0 -1.5707963267948966 1.5707963267948966" xyz="0 0 0" />
        <parent link="robotiq_ft300_frame_id" />
        <child link="robotiq_ft300_toolside" />
    </joint>
    <!--
    NOTE: the macros defined in this file are NOT part of the public API of this
          package. Users CANNOT rely on this file being available, or stored in
          this location. Nor can they rely on the existence of the two macros.

    Author: Ludovic Delval
    Contributor: Felix Messmer
  -->
    <link name="dual_gripper_coupling_robotside">
        <inertial>
            <!-- Computed from Solidworks, matches the Robotiq datasheet (2021/06/23) -->
            <origin rpy="0 0 0" xyz="0.01545 0 0" />
            <!-- From Robotiq datasheet (2021/06/23) -->
            <mass value="0.265" />
            <inertia ixx="0" ixy="0" ixz="0" iyy="0" iyz="0" izz="0" />
        </inertial>
        <visual>
            <origin rpy="0 0 0" xyz="0 0 0" />
            <geometry>
                <mesh filename="package://robotiq_description/meshes/robotiq_agc_apl_159_002/visual/agc_apl_159_002.dae" />
            </geometry>
            <material name="">
                <color rgba="0.792156862745098 0.819607843137255 0.933333333333333 1" />
            </material>
        </visual>
        <collision>
            <origin rpy="0 0 0" xyz="0 0 0" />
            <geometry>
                <mesh filename="package://robotiq_description/meshes/robotiq_agc_apl_159_002/collision/bbox/agc_apl_159_002.stl" />
            </geometry>
        </collision>
    </link>
    <link name="dual_gripper_coupling_toolside_left" />
    <link name="dual_gripper_coupling_toolside_right" />
    <joint name="dual_gripper_coupling_toolside_left_joint" type="fixed">
        <origin rpy="0 0 0.7853981633974483" xyz="0.027 0.043 0" />
        <parent link="dual_gripper_coupling_robotside" />
        <child link="dual_gripper_coupling_toolside_left" />
    </joint>
    <joint name="dual_gripper_coupling_toolside_right_joint" type="fixed">
        <origin rpy="0 0 -0.7853981633974483" xyz="0.027 -0.043 0" />
        <parent link="dual_gripper_coupling_robotside" />
        <child link="dual_gripper_coupling_toolside_right" />
    </joint>
    <!-- TODO measure or calculate -->
    <link name="camera_adapter_robotside">
        <inertial>
            <origin rpy="0 0 0" xyz="0 0 0" />
            <mass value="0.2" />
            <inertia ixx="0" ixy="0" ixz="0" iyy="0" iyz="0" izz="0" />
        </inertial>
        <visual>
            <origin rpy="0 0 0" xyz="0 0 0" />
            <geometry>
                <mesh filename="package://oscar_description/meshes/oscar/realsense_camera_adapter/visual/realsense_camera_adapter_1k.dae" />
            </geometry>
            <material name="">
                <color rgba="0.79216 0.81961 0.93333 1" />
            </material>
        </visual>
        <collision>
            <origin rpy="0 0 0" xyz="0 0 0" />
            <geometry>
                <mesh filename="package://oscar_description/meshes/oscar/realsense_camera_adapter/collision/realsense_camera_adapter_bbox.stl" />
            </geometry>
        </collision>
    </link>
    <link name="camera_adapter_toolside" />
    <joint name="camera_adapter_toolside_joint" type="fixed">
        <!-- Original CAD -->
        <origin rpy="0 0 0" xyz="0.045 0 0.016" />
        <parent link="camera_adapter_robotside" />
        <child link="camera_adapter_toolside" />
    </joint>
    <!-- camera body, with origin at bottom screw mount -->
    <joint name="camera_joint" type="fixed">
        <origin rpy="0 0 0" xyz="0.010025 0 -0.0115" />
        <parent link="camera_adapter_toolside" />
        <child link="camera_bottom_screw_frame" />
    </joint>
    <link name="camera_bottom_screw_frame" />
    <joint name="camera_link_joint" type="fixed">
        <origin rpy="0 0 0" xyz="0 0.02 0.0115" />
        <parent link="camera_bottom_screw_frame" />
        <child link="camera_link" />
    </joint>
    <link name="camera_link">
        <visual>
            <origin rpy="1.5707963267948966 0 1.5707963267948966" xyz="0.00987 -0.02 0" />
            <geometry>
                <mesh filename="package://realsense2_description/meshes/d415.stl" />
            </geometry>
            <material name="aluminum" />
        </visual>
        <collision>
            <origin rpy="0 0 0" xyz="0 -0.02 0" />
            <geometry>
                <box size="0.02005 0.099 0.023" />
            </geometry>
        </collision>
        <inertial>
            <mass value="0.072" />
            <!-- The following are not reliable values, and should not be used for modeling -->
            <origin xyz="0 0 0" rpy="0 0 0" />
            <inertia ixx="0.003881243" ixy="0.0" ixz="0.0" iyy="0.000498940" iyz="0.0" izz="0.003879257" />
        </inertial>
    </link>
    <joint name="camera_usb_plug_joint" type="fixed">
        <origin rpy="0 0 0" xyz="-0.005999999999999998 -0.0558 0" />
        <parent link="camera_link" />
        <child link="camera_usb_plug_link" />
    </joint>
    <link name="camera_usb_plug_link">
        <visual>
            <!-- 0.044850 0.008000 0.018500 -->
            <origin rpy="0 0 1.5707963267948966" xyz="0. -0.022425 0." />
            <geometry>
                <!--box size="0.044850 0.008 0.0185" /-->
                <mesh filename="package://realsense2_description/meshes/plug.stl" />
            </geometry>
            <material name="plastic" />
        </visual>
        <collision>
            <origin rpy="0 0 1.5707963267948966" xyz="0. -0.022425 0." />
            <geometry>
                <!--box size="0.044850 0.008 0.0185" /-->
                <mesh filename="package://realsense2_description/meshes/plug_collision.stl" />
            </geometry>
        </collision>
        <inertial>
            <mass value="0.1" />
            <origin xyz="0 0 0" rpy="0 0 0" />
            <inertia ixx="0.03" iyy="0.03" izz="0.03" ixy="0.0" ixz="0.0" iyz="0.0" />
        </inertial>
    </link>
    <!--
    NOTE: the macros defined in this file are NOT part of the public API of this
          package. Users CANNOT rely on this file being available, or stored in
          this location. Nor can they rely on the existence of the two macros.

    Author: Ludovic Delval
    Contributor: Felix Messmer
  -->
    <link name="robotiq_2f140_base_link">
        <inertial>
            <origin rpy="0 0 0" xyz="0.0349137712216298 -0.000307415638406242 -1.86112821823436E-05" />
            <mass value="0.124496292726075" />
            <inertia ixx="1.77198801578171E-05" ixy="-1.20168637369256E-06" ixz="-7.33154410139097E-08" iyy="6.51416874558209E-05" iyz="-3.67584779427649E-09" izz="4.97965327837907E-05" />
        </inertial>
        <visual>
            <origin rpy="0 0 0" xyz="0 0 0" />
            <geometry>
                <mesh filename="package://robotiq_description/meshes/robotiq_2f_140/visual/base.dae" />
            </geometry>
            <material name="">
                <color rgba="0.752941176470588 0.752941176470588 0.752941176470588 1" />
            </material>
        </visual>
        <collision>
            <origin rpy="0 0 0" xyz="0 0 0" />
            <geometry>
                <mesh filename="package://robotiq_description/meshes/robotiq_2f_140/collision/bbox/base.stl" />
            </geometry>
        </collision>
    </link>
    <link name="robotiq_2f140_left_outer_knuckle">
        <inertial>
            <origin rpy="0 0 0" xyz="0.000553430078305425 -0.0113324166394055 -2.069203532776E-08" />
            <mass value="0.00786620962275458" />
            <inertia ixx="0" ixy="0" ixz="0" iyy="0" iyz="0" izz="0" />
        </inertial>
        <visual>
            <origin rpy="0 0 0" xyz="0 0 0" />
            <geometry>
                <mesh filename="package://robotiq_description/meshes/robotiq_2f_140/visual/outer_knuckle.dae" />
            </geometry>
            <material name="">
                <color rgba="0.792156862745098 0.819607843137255 0.933333333333333 1" />
            </material>
        </visual>
        <collision>
            <origin rpy="0 0 0" xyz="0 0 0" />
            <geometry>
                <mesh filename="package://robotiq_description/meshes/robotiq_2f_140/collision/bbox/outer_knuckle.stl" />
            </geometry>
        </collision>
    </link>
    <link name="robotiq_2f140_left_outer_finger">
        <inertial>
            <origin rpy="0 0 0" xyz="0.037582513422451 -0.0147933878405319 1.75722175258395E-09" />
            <mass value="0.0164998179601088" />
            <inertia ixx="3.63881150640202E-07" ixy="7.77163079871056E-07" ixz="3.83932554975091E-15" iyy="1.72399139003576E-06" iyz="-6.12077326039638E-15" izz="2.0741644702864E-06" />
        </inertial>
        <visual>
            <origin rpy="0 0 0" xyz="0 0 0" />
            <geometry>
                <mesh filename="package://robotiq_description/meshes/robotiq_2f_140/visual/outer_finger.dae" />
            </geometry>
            <material name="">
                <color rgba="0.752941176470588 0.752941176470588 0.752941176470588 1" />
            </material>
        </visual>
        <collision>
            <origin rpy="0 0 0" xyz="0 0 0" />
            <geometry>
                <mesh filename="package://robotiq_description/meshes/robotiq_2f_140/collision/bbox/outer_finger.stl" />
            </geometry>
        </collision>
    </link>
    <link name="robotiq_2f140_left_inner_finger">
        <inertial>
            <origin rpy="0 0 0" xyz="0.0138261523043157 0.012041065004881 -2.07110001536426E-15" />
            <mass value="0.00728069074391804" />
            <inertia ixx="2.80233056217759E-09" ixy="-1.06385436552863E-08" ixz="-6.39274552405216E-21" iyy="5.288119896764E-08" iyz="-1.63868227162773E-21" izz="5.56835295298176E-08" />
        </inertial>
        <visual>
            <origin rpy="0 0 0" xyz="0 0 0" />
            <geometry>
                <mesh filename="package://robotiq_description/meshes/robotiq_2f_140/visual/inner_finger.dae" />
            </geometry>
            <material name="">
                <color rgba="0.752941176470588 0.752941176470588 0.752941176470588 1" />
            </material>
        </visual>
        <collision>
            <origin rpy="0 0 0" xyz="0 0 0" />
            <geometry>
                <mesh filename="package://robotiq_description/meshes/robotiq_2f_140/collision/bbox/inner_finger.stl" />
            </geometry>
        </collision>
    </link>
    <link name="robotiq_2f140_left_fingertip">
        <inertial>
            <origin rpy="0 0 0" xyz="-0.000109801182224895 0.00317755672771076 6.71012101645093E-17" />
            <mass value="0.0110245686419432" />
            <inertia ixx="2.08902759828054E-08" ixy="4.60038120722903E-10" ixz="1.38333794517888E-23" iyy="1.01307935181161E-11" iyz="-6.28172104669565E-22" izz="2.09004067763235E-08" />
        </inertial>
        <visual>
            <origin rpy="0 0 0" xyz="0 0 0" />
            <geometry>
                <mesh filename="package://robotiq_description/meshes/robotiq_2f_140/visual/fingertip.dae" />
            </geometry>
            <material name="">
                <color rgba="0.792156862745098 0.819607843137255 0.933333333333333 1" />
            </material>
        </visual>
        <collision>
            <origin rpy="0 0 0" xyz="0 0 0" />
            <geometry>
                <mesh filename="package://robotiq_description/meshes/robotiq_2f_140/collision/bbox/fingertip.stl" />
            </geometry>
        </collision>
    </link>
    <link name="robotiq_2f140_left_inner_knuckle">
        <inertial>
            <origin rpy="0 0 0" xyz="0.0361850676948983 -0.0331675189831137 -1.21207146841943E-08" />
            <mass value="0.0174460087279995" />
            <inertia ixx="1.15871030484505E-06" ixy="1.18962145386134E-06" ixz="-8.39568250113456E-14" iyy="1.41683380026142E-06" iyz="6.84207447322716E-14" izz="2.39357586071014E-06" />
        </inertial>
        <visual>
            <origin rpy="0 0 0" xyz="0 0 0" />
            <geometry>
                <mesh filename="package://robotiq_description/meshes/robotiq_2f_140/visual/inner_knuckle.dae" />
            </geometry>
            <material name="">
                <color rgba="0.752941176470588 0.752941176470588 0.752941176470588 1" />
            </material>
        </visual>
        <collision>
            <origin rpy="0 0 0" xyz="0 0 0" />
            <geometry>
                <mesh filename="package://robotiq_description/meshes/robotiq_2f_140/collision/bbox/inner_knuckle.stl" />
            </geometry>
        </collision>
    </link>
    <!--
    NOTE: the macros defined in this file are NOT part of the public API of this
          package. Users CANNOT rely on this file being available, or stored in
          this location. Nor can they rely on the existence of the two macros.

    Author: Ludovic Delval
    Contributor: Felix Messmer
  -->
    <!-- Link representing the silicon finger tip pad -->
    <link name="robotiq_2f140_left_fingertip_pad">
        <inertial>
            <origin rpy="0 0 0" xyz="0.00227643166121317 -0.00163641909670073 -0.000186465195632485" />
            <mass value="0.0212636185801172" />
            <inertia ixx="0" ixy="0" ixz="0" iyy="0" iyz="0" izz="0" />
        </inertial>
        <visual>
            <origin rpy="0 0 0" xyz="0 0 0" />
            <geometry>
                <mesh filename="package://robotiq_description/meshes/robotiq_agc_tip_220_140/visual/agc_tip_220_140.dae" />
            </geometry>
            <material name="">
                <color rgba="0.0392156862745098 0.0392156862745098 0.0392156862745098 1" />
            </material>
        </visual>
        <collision>
            <origin rpy="0 0 0" xyz="0 0 0" />
            <geometry>
                <mesh filename="package://robotiq_description/meshes/robotiq_agc_tip_220_140/collision/agc_tip_220_140.stl" />
            </geometry>
        </collision>
    </link>
    <link name="robotiq_2f140_right_outer_knuckle">
        <inertial>
            <origin rpy="0 0 0" xyz="0.000553430078305425 -0.0113324166394055 -2.069203532776E-08" />
            <mass value="0.00786620962275458" />
            <inertia ixx="0" ixy="0" ixz="0" iyy="0" iyz="0" izz="0" />
        </inertial>
        <visual>
            <origin rpy="0 0 0" xyz="0 0 0" />
            <geometry>
                <mesh filename="package://robotiq_description/meshes/robotiq_2f_140/visual/outer_knuckle.dae" />
            </geometry>
            <material name="">
                <color rgba="0.792156862745098 0.819607843137255 0.933333333333333 1" />
            </material>
        </visual>
        <collision>
            <origin rpy="0 0 0" xyz="0 0 0" />
            <geometry>
                <mesh filename="package://robotiq_description/meshes/robotiq_2f_140/collision/bbox/outer_knuckle.stl" />
            </geometry>
        </collision>
    </link>
    <link name="robotiq_2f140_right_outer_finger">
        <inertial>
            <origin rpy="0 0 0" xyz="0.037582513422451 -0.0147933878405319 1.75722175258395E-09" />
            <mass value="0.0164998179601088" />
            <inertia ixx="3.63881150640202E-07" ixy="7.77163079871056E-07" ixz="3.83932554975091E-15" iyy="1.72399139003576E-06" iyz="-6.12077326039638E-15" izz="2.0741644702864E-06" />
        </inertial>
        <visual>
            <origin rpy="0 0 0" xyz="0 0 0" />
            <geometry>
                <mesh filename="package://robotiq_description/meshes/robotiq_2f_140/visual/outer_finger.dae" />
            </geometry>
            <material name="">
                <color rgba="0.752941176470588 0.752941176470588 0.752941176470588 1" />
            </material>
        </visual>
        <collision>
            <origin rpy="0 0 0" xyz="0 0 0" />
            <geometry>
                <mesh filename="package://robotiq_description/meshes/robotiq_2f_140/collision/bbox/outer_finger.stl" />
            </geometry>
        </collision>
    </link>
    <link name="robotiq_2f140_right_inner_finger">
        <inertial>
            <origin rpy="0 0 0" xyz="0.0138261523043157 0.012041065004881 -2.07110001536426E-15" />
            <mass value="0.00728069074391804" />
            <inertia ixx="2.80233056217759E-09" ixy="-1.06385436552863E-08" ixz="-6.39274552405216E-21" iyy="5.288119896764E-08" iyz="-1.63868227162773E-21" izz="5.56835295298176E-08" />
        </inertial>
        <visual>
            <origin rpy="0 0 0" xyz="0 0 0" />
            <geometry>
                <mesh filename="package://robotiq_description/meshes/robotiq_2f_140/visual/inner_finger.dae" />
            </geometry>
            <material name="">
                <color rgba="0.752941176470588 0.752941176470588 0.752941176470588 1" />
            </material>
        </visual>
        <collision>
            <origin rpy="0 0 0" xyz="0 0 0" />
            <geometry>
                <mesh filename="package://robotiq_description/meshes/robotiq_2f_140/collision/bbox/inner_finger.stl" />
            </geometry>
        </collision>
    </link>
    <link name="robotiq_2f140_right_fingertip">
        <inertial>
            <origin rpy="0 0 0" xyz="-0.000109801182224895 0.00317755672771076 6.71012101645093E-17" />
            <mass value="0.0110245686419432" />
            <inertia ixx="2.08902759828054E-08" ixy="4.60038120722903E-10" ixz="1.38333794517888E-23" iyy="1.01307935181161E-11" iyz="-6.28172104669565E-22" izz="2.09004067763235E-08" />
        </inertial>
        <visual>
            <origin rpy="0 0 0" xyz="0 0 0" />
            <geometry>
                <mesh filename="package://robotiq_description/meshes/robotiq_2f_140/visual/fingertip.dae" />
            </geometry>
            <material name="">
                <color rgba="0.792156862745098 0.819607843137255 0.933333333333333 1" />
            </material>
        </visual>
        <collision>
            <origin rpy="0 0 0" xyz="0 0 0" />
            <geometry>
                <mesh filename="package://robotiq_description/meshes/robotiq_2f_140/collision/bbox/fingertip.stl" />
            </geometry>
        </collision>
    </link>
    <link name="robotiq_2f140_right_inner_knuckle">
        <inertial>
            <origin rpy="0 0 0" xyz="0.0361850676948983 -0.0331675189831137 -1.21207146841943E-08" />
            <mass value="0.0174460087279995" />
            <inertia ixx="1.15871030484505E-06" ixy="1.18962145386134E-06" ixz="-8.39568250113456E-14" iyy="1.41683380026142E-06" iyz="6.84207447322716E-14" izz="2.39357586071014E-06" />
        </inertial>
        <visual>
            <origin rpy="0 0 0" xyz="0 0 0" />
            <geometry>
                <mesh filename="package://robotiq_description/meshes/robotiq_2f_140/visual/inner_knuckle.dae" />
            </geometry>
            <material name="">
                <color rgba="0.752941176470588 0.752941176470588 0.752941176470588 1" />
            </material>
        </visual>
        <collision>
            <origin rpy="0 0 0" xyz="0 0 0" />
            <geometry>
                <mesh filename="package://robotiq_description/meshes/robotiq_2f_140/collision/bbox/inner_knuckle.stl" />
            </geometry>
        </collision>
    </link>
    <!--
    NOTE: the macros defined in this file are NOT part of the public API of this
          package. Users CANNOT rely on this file being available, or stored in
          this location. Nor can they rely on the existence of the two macros.

    Author: Ludovic Delval
    Contributor: Felix Messmer
  -->
    <!-- Link representing the silicon finger tip pad -->
    <link name="robotiq_2f140_right_fingertip_pad">
        <inertial>
            <origin rpy="0 0 0" xyz="0.00227643166121317 -0.00163641909670073 -0.000186465195632485" />
            <mass value="0.0212636185801172" />
            <inertia ixx="0" ixy="0" ixz="0" iyy="0" iyz="0" izz="0" />
        </inertial>
        <visual>
            <origin rpy="0 0 0" xyz="0 0 0" />
            <geometry>
                <mesh filename="package://robotiq_description/meshes/robotiq_agc_tip_220_140/visual/agc_tip_220_140.dae" />
            </geometry>
            <material name="">
                <color rgba="0.0392156862745098 0.0392156862745098 0.0392156862745098 1" />
            </material>
        </visual>
        <collision>
            <origin rpy="0 0 0" xyz="0 0 0" />
            <geometry>
                <mesh filename="package://robotiq_description/meshes/robotiq_agc_tip_220_140/collision/agc_tip_220_140.stl" />
            </geometry>
        </collision>
    </link>
    <joint name="robotiq_2f140_left_outer_knuckle_joint" type="revolute">
        <origin rpy="0 3.141592653589793 3.141592653589793" xyz="0.062905 0.030601 0" />
        <parent link="robotiq_2f140_base_link" />
        <child link="robotiq_2f140_left_outer_knuckle" />
        <axis xyz="0 0 1" />
        <limit effort="176" lower="0" upper="0.792" velocity="2.0" />
    </joint>
    <joint name="robotiq_2f140_left_outer_finger_joint" type="fixed">
        <origin rpy="0 0 0" xyz="-0.0045554 -0.031421 0" />
        <parent link="robotiq_2f140_left_outer_knuckle" />
        <child link="robotiq_2f140_left_outer_finger" />
    </joint>
    <joint name="robotiq_2f140_left_inner_knuckle_joint" type="revolute">
        <origin rpy="0.0 0.0 0.0" xyz="0.06942 -0.0127 0" />
        <parent link="robotiq_2f140_base_link" />
        <child link="robotiq_2f140_left_inner_knuckle" />
        <axis xyz="0 0 1" />
        <limit effort="176" lower="-3.14" upper="3.14" velocity="2.0" />
        <mimic joint="robotiq_2f140_left_outer_knuckle_joint" multiplier="1" offset="0" />
    </joint>
    <joint name="robotiq_2f140_left_inner_finger_joint" type="revolute">
        <origin rpy="0 0 0" xyz="0.078873 -0.035489 0" />
        <parent link="robotiq_2f140_left_outer_finger" />
        <child link="robotiq_2f140_left_inner_finger" />
        <axis xyz="0 0 1" />
        <limit effort="176" lower="-3.14" upper="3.14" velocity="2.0" />
        <mimic joint="robotiq_2f140_left_outer_knuckle_joint" multiplier="-1" offset="0" />
    </joint>
    <joint name="robotiq_2f140_left_fingertip_joint" type="fixed">
        <origin rpy="0 0 0" xyz="0.046015 0.018901 0" />
        <parent link="robotiq_2f140_left_inner_finger" />
        <child link="robotiq_2f140_left_fingertip" />
    </joint>
    <joint name="robotiq_2f140_left_fingertip_pad_joint" type="fixed">
        <origin rpy="0 0 0" xyz="0 0.00476 0 " />
        <parent link="robotiq_2f140_left_fingertip" />
        <child link="robotiq_2f140_left_fingertip_pad" />
    </joint>
    <joint name="robotiq_2f140_right_outer_knuckle_joint" type="revolute">
        <origin rpy="0 0 0" xyz="0.062905 -0.030601 0" />
        <parent link="robotiq_2f140_base_link" />
        <child link="robotiq_2f140_right_outer_knuckle" />
        <axis xyz="0 0 1" />
        <limit effort="176" lower="-3.14" upper="3.14" velocity="2.0" />
        <mimic joint="robotiq_2f140_left_outer_knuckle_joint" multiplier="1" offset="0" />
    </joint>
    <joint name="robotiq_2f140_right_outer_finger_joint" type="fixed">
        <origin rpy="0 0 0" xyz="-0.0045554 -0.031421 0" />
        <parent link="robotiq_2f140_right_outer_knuckle" />
        <child link="robotiq_2f140_right_outer_finger" />
    </joint>
    <joint name="robotiq_2f140_right_inner_knuckle_joint" type="revolute">
        <origin rpy="-0.0 -3.141592653589793 -3.141592653589793" xyz="0.06942 0.0127 0" />
        <parent link="robotiq_2f140_base_link" />
        <child link="robotiq_2f140_right_inner_knuckle" />
        <axis xyz="0 0 1" />
        <limit effort="176" lower="-3.14" upper="3.14" velocity="2.0" />
        <mimic joint="robotiq_2f140_left_outer_knuckle_joint" multiplier="1" offset="0" />
    </joint>
    <joint name="robotiq_2f140_right_inner_finger_joint" type="revolute">
        <origin rpy="0 0 0" xyz="0.078873 -0.035489 0" />
        <parent link="robotiq_2f140_right_outer_finger" />
        <child link="robotiq_2f140_right_inner_finger" />
        <axis xyz="0 0 1" />
        <limit effort="176" lower="-3.14" upper="3.14" velocity="2.0" />
        <mimic joint="robotiq_2f140_left_outer_knuckle_joint" multiplier="-1" offset="0" />
    </joint>
    <joint name="robotiq_2f140_right_fingertip_joint" type="fixed">
        <origin rpy="0 0 0" xyz="0.046015 0.018901 0" />
        <parent link="robotiq_2f140_right_inner_finger" />
        <child link="robotiq_2f140_right_fingertip" />
    </joint>
    <joint name="robotiq_2f140_right_fingertip_pad_joint" type="fixed">
        <origin rpy="0 0 0" xyz="0 0.00476 0 " />
        <parent link="robotiq_2f140_right_fingertip" />
        <child link="robotiq_2f140_right_fingertip_pad" />
    </joint>
    <transmission name="robotiq_2f140_finger_joint_trans">
        <type>transmission_interface/SimpleTransmission</type>
        <joint name="robotiq_2f140_finger_joint">
            <hardwareInterface>PositionJointInterface</hardwareInterface>
        </joint>
        <actuator name="robotiq_2f140_finger_joint_motor">
            <mechanicalReduction>1</mechanicalReduction>
        </actuator>
    </transmission>
    <!-- TODO measure or calculate -->
    <link name="pipette_base">
        <inertial>
            <origin rpy="0 0 0" xyz="0 0 0" />
            <mass value="0.5" />
            <inertia ixx="0" ixy="0" ixz="0" iyy="0" iyz="0" izz="0" />
        </inertial>
        <visual>
            <origin rpy="0 0 0" xyz="0 0 0" />
            <geometry>
                <mesh filename="package://oscar_description/meshes/oscar/pipette_p200/visual/9k.dae" />
            </geometry>
            <material name="">
                <color rgba="0.79216 0.81961 0.93333 1" />
            </material>
        </visual>
        <collision>
            <origin rpy="0 0 0" xyz="0 0 0" />
            <geometry>
                <mesh filename="package://oscar_description/meshes/udes/pipette_p200/collision/pipette_p200_coarse.stl" />
            </geometry>
        </collision>
    </link>
    <link name="pipette_tip" />
    <joint name="pipette_tip_joint" type="fixed">
        <!-- Original CAD -->
        <origin rpy="0 0 0" xyz="0.253442 0 0" />
        <parent link="pipette_base" />
        <child link="pipette_tip" />
    </joint>
    <joint name="newport_base_joint" type="fixed">
        <parent link="floor" />
        <child link="newport_base" />
        <!-- Offset by 1.5 inch for mounting foot height -->
        <origin rpy="0.0 0.0 0.0" xyz="-0.055 -0.0675 0.6604" />
    </joint>
    <joint name="back_wall_joint" type="fixed">
        <parent link="floor" />
        <child link="back_wall" />
        <origin rpy="0.0 0.0 0.0" xyz="0.6145999999999999 0 1.2373" />
    </joint>
    <joint name="hut_wall_joint" type="fixed">
        <parent link="floor" />
        <child link="hut_wall" />
        <origin rpy="0.0 0.0 0.0" xyz="0 0.7671 1.2373" />
    </joint>
    <joint name="counter_wall_joint" type="fixed">
        <parent link="floor" />
        <child link="counter_wall" />
        <origin rpy="0.0 0.0 0.0" xyz="0 -0.7671 1.2373" />
    </joint>
    <joint name="ur3_mounting_plate_base_joint" type="fixed">
        <parent link="newport_tabletop" />
        <child link="ur3_mounting_plate_base" />
        <!-- Newport tabletop has matrix of 1 inch hole gap-->
        <origin rpy="0.0 0.0 0.0" xyz="0.0 -0.0254  0.0" />
    </joint>
    <joint name="ur3_base_joint" type="fixed">
        <parent link="ur3_mounting_plate_robotside" />
        <child link="panda_link0" />
        <origin rpy="0.0 0.0 3.141592653589793" xyz="0.0 0.0 0.0" />
    </joint>
    <joint name="robotiq_fts300_coupling_joint" type="fixed">
        <parent link="ur3_flange" />
        <child link="robotiq_ft300_coupling_robotside" />
        <!-- Align mounting plate to flange -->
        <origin rpy="3.141592653589793 0.0 0.0" xyz="0.0 0.0 0.0" />
    </joint>
    <joint name="robotiq_ft300_joint" type="fixed">
        <parent link="robotiq_ft300_coupling_toolside" />
        <child link="robotiq_ft300_robotside" />
        <origin rpy="0 0.0 0.0" xyz="0.0 0.0 0.0" />
    </joint>
    <joint name="dual_gripper_coupling_robotside_joint" type="fixed">
        <parent link="robotiq_ft300_toolside" />
        <child link="dual_gripper_coupling_robotside" />
        <origin rpy="0.0 0.0 0.0" xyz="0.0 0.0 0.0" />
    </joint>
    <joint name="robotiq_2f140_base_joint" type="fixed">
        <parent link="dual_gripper_coupling_toolside_left" />
        <child link="robotiq_2f140_base_link" />
        <!-- <origin xyz="0.0 0.0 0.0" rpy="0 0 0" /> -->
        <origin rpy="3.141592653589793 0 0" xyz="0.00160516037 0.00101565847 -0.00215532428" />
    </joint>
    <joint name="camera_adapter_robotside_joint" type="fixed">
        <parent link="robotiq_2f140_base_link" />
        <child link="camera_adapter_robotside" />
        <origin rpy="3.141592653589793 0 0" xyz="0.0443 0 -0.0385" />
    </joint>
    <!-- Calibrated with moveit_calibration pkg on 14/01/2025 (N = 5 samples)
       Reprojection error:
           Translation = 0.0006048 meters
           Rotation    = 0.00143 radians

       WARNING: in realsense launcher, set tf_publish to false or it will change this tf
  -->
    <link name="camera_color_optical_frame_pre" />
    <joint name="camera_color_optical_frame_pre_joint" type="fixed">
        <parent link="ur3_flange" />
        <child link="camera_color_optical_frame_pre" />
        <!-- The RPY given by moveit_calibration is erroneous see:
         https://github.com/moveit/moveit_calibration/issues/132 -->
        <origin rpy="0.0255219 -0.7837478 -0.0339841" xyz="-0.137124 -0.0522788 0.106907" />
    </joint>
    <link name="camera_color_optical_frame" />
    <joint name="camera_color_optical_frame_joint" type="fixed">
        <parent link="camera_color_optical_frame_pre" />
        <child link="camera_color_optical_frame" />
        <!-- We add 20mm to achieve better accuracy after some test, the Charucobaord
         board appeared elavated by ~16mm wrt. the URDF tabletop (newport_tabletop frame) -->
        <!-- <origin xyz="0 0 0.02" rpy="0 0 0" /> -->
        <origin rpy="0 0 0" xyz="0 0 0.013" />
    </joint>
    <!-- Tool center point origin on the fingertip end when the gripper is fully closed -->
    <link name="robotiq_2f140_tcp" />
    <joint name="robotiq_2f140_tcp_joint" type="fixed">
        <origin rpy="3.141592653589793 0 0" xyz="0.24127678495 0 0" />
        <parent link="robotiq_2f140_base_link" />
        <child link="robotiq_2f140_tcp" />
    </joint>
    <link name="robotiq_2f140_tcp_cad" />
    <joint name="robotiq_2f140_tcp_cad_joint" type="fixed">
        <parent link="dual_gripper_coupling_toolside_left" />
        <child link="robotiq_2f140_tcp_cad" />
        <origin rpy="0 0 0" xyz="0.24127678495 0 0" />
    </joint>
    <!-- Offset mesh to match pipette_tcp link calibration -->
    <joint name="pipette_base_joint" type="fixed">
        <parent link="dual_gripper_coupling_toolside_right" />
        <child link="pipette_base" />
        <!-- <origin xyz="0.00151316 -0.001407139 0.00353" rpy="${pi} 0.0 0.0" /> -->
        <!-- add small offset to match real setup Z axis 1.25 mm -->
        <origin rpy="3.141592653589793 0.0 0.0" xyz="0.00151316 -0.001407139 0.00228" />
    </joint>
    <link name="pipette_tcp" />
    <joint name="pipette_tcp_joint" type="fixed">
        <parent link="pipette_tip" />
        <child link="pipette_tcp" />
        <!-- Rotate around X axis by PI

         Change the rotation so that it matches the calibrated point
         with a tip when adding the tip along the X axis.
    -->
        <origin rpy="-3.1415927 0.0272858 1e-7" xyz="0 0 0" />
    </joint>
    <!-- <link name="pipette_tcp_validation"/> -->
    <!-- <joint name="pipette_tcp_validation_joint" type="fixed"> -->
    <!--   <parent link= "pipette_tcp" /> -->
    <!--   <child link = "pipette_tcp_validation" /> -->
    <!--   <!-\- <origin xyz="0 0 0" rpy="${pi} 0 0" /> -\-> -->
    <!--   <origin xyz="0.0458171 0 0" rpy="0 0 0" /> -->
    <!-- </joint> -->
    <!-- Calibrated with the UR3 Teach Pendant on 17/01/2025 (N = 4 samples) dowel pin located on JJ24 newport tabletop -->
    <!-- <link name="pipette_with_tip_tcp_pre"/> -->
    <!-- <joint name="pipette_with_tip_tcp_joint_pre" type="fixed"> -->
    <!--   <parent link= "ur3_tool0" /> -->
    <!--   <child link = "pipette_with_tip_tcp_pre" /> -->
    <!--   <!-\- The rotation given by the teach pendant is wrt. the UR3 base frame -->
    <!--        X = 0.26253 -->
    <!--        Y = -0.00353 -->
    <!--        Z = 0.28204 -->
    <!--        Axis with angle magnitude -->
    <!--        RX = -1.7569 -->
    <!--        RY = -1.7511 -->
    <!--        RZ = 0.7206 -->
    <!--        Converted to URDF RPY: -->
    <!--        R = -2.3521618 -->
    <!--        P = -0.0085883 -->
    <!--        Y = 1.5639119 -->
    <!--        Rotate the frame so that the +X axis points away from the pipette tip (Y=PI/2, Z=PI) -->
    <!--        Currently in the newport tabletop by: -0.008388061879533032 -->
    <!--   -\-> -->
    <!--   <origin xyz="0.26253 -0.00353 0.28204" rpy="1.5707963 -0.7853981 0" /> -->
    <!-- </joint> -->
    <!-- <!-\- Adjust for real world height table -\-> -->
    <!-- <link name="pipette_with_tip_tcp"/> -->
    <!-- <joint name="pipette_with_tip_tcp_joint" type="fixed"> -->
    <!--   <parent link= "pipette_with_tip_tcp_pre" /> -->
    <!--   <child link = "pipette_with_tip_tcp" /> -->
    <!--   <origin xyz="-0.0083 0 0" rpy="0 0 0" /> -->
    <!-- </joint> -->
    <!-- Start from the calibrated TCP with tip and move upwards by -X units
       Found experimentally:
         w/  tip: -173.47mm (Base Z axis)
         w/o tip: -219.27mm ...
         X = 45.8mm

         +9.2mm difference with the latest calibration in the Z axis

         tip head
         frame.p = KDL::Vector(0, 0, 0.0456);
         TODO

  -->
    <!-- <link name="pipette_tcp_from_tool0"/> -->
    <!-- <joint name="pipette_tcp_from_tool0_joint" type="fixed"> -->
    <!--   <parent link= "pipette_with_tip_tcp" /> -->
    <!--   <child link = "pipette_tcp_from_tool0" /> -->
    <!--   <origin xyz="-0.0458 0 0" rpy="0 0 0" /> -->
    <!-- </joint> -->
    <!-- Conveniance frame -->
    <!-- <link name="pipette_tcp_old"/> -->
    <!-- <joint name="pipette_tcp_old_joint" type="fixed"> -->
    <!--   <parent link= "pipette_tip" /> -->
    <!--   <child link = "pipette_tcp_old" /> -->
    <!--   <!-\- Calibrated on Apr 18 2024 with Tool Point Calibration ROS package -\-> -->
    <!--   <!-\- Calibration captured 4 tool poses (out of 4 requested). Computing calibration... -\-> -->
    <!--   <!-\- Calibrated tcp (meters in xyz): [   0.223439 -0.00046209    0.243363] from ur3_tool0 -\-> -->
    <!--   <!-\- Touch point (meters in xyz): [-0.240945  0.241088 0.0427421] in frame newport_tabletop -\-> -->
    <!--   <!-\- Average residual: 1.43073e-07 -\-> -->
    <!--   <!-\- <origin xyz="0.0006228806938889386 0.0011144002871499858 -0.00046208999999987344" rpy="0.0 0.0 0.0" /> -\-> -->
    <!--   <origin xyz="0.0006464523002427391 0.0005510077330404747 -0.0007046087554606569" rpy="${pi} 0.0 0.0" /> -->
    <!-- </joint> -->
    <transmission name="trans_panda_joint1">
        <type>transmission_interface/SimpleTransmission</type>
        <joint name="panda_joint1">
            <hardwareInterface>hardware_interface/EffortJointInterface</hardwareInterface>
        </joint>
        <actuator name="panda_joint1_motor">
            <hardwareInterface>hardware_interface/EffortJointInterface</hardwareInterface>
            <mechanicalReduction>1</mechanicalReduction>
        </actuator>
    </transmission>
    <transmission name="trans_panda_joint2">
        <type>transmission_interface/SimpleTransmission</type>
        <joint name="panda_joint2">
            <hardwareInterface>hardware_interface/EffortJointInterface</hardwareInterface>
        </joint>
        <actuator name="panda_joint2_motor">
            <hardwareInterface>hardware_interface/EffortJointInterface</hardwareInterface>
            <mechanicalReduction>1</mechanicalReduction>
        </actuator>
    </transmission>
    <transmission name="trans_panda_joint3">
        <type>transmission_interface/SimpleTransmission</type>
        <joint name="panda_joint3">
            <hardwareInterface>hardware_interface/EffortJointInterface</hardwareInterface>
        </joint>
        <actuator name="panda_joint3_motor">
            <hardwareInterface>hardware_interface/EffortJointInterface</hardwareInterface>
            <mechanicalReduction>1</mechanicalReduction>
        </actuator>
    </transmission>
    <transmission name="trans_panda_joint4">
        <type>transmission_interface/SimpleTransmission</type>
        <joint name="panda_joint4">
            <hardwareInterface>hardware_interface/EffortJointInterface</hardwareInterface>
        </joint>
        <actuator name="panda_joint4_motor">
            <hardwareInterface>hardware_interface/EffortJointInterface</hardwareInterface>
            <mechanicalReduction>1</mechanicalReduction>
        </actuator>
    </transmission>
    <transmission name="trans_panda_joint5">
        <type>transmission_interface/SimpleTransmission</type>
        <joint name="panda_joint5">
            <hardwareInterface>hardware_interface/EffortJointInterface</hardwareInterface>
        </joint>
        <actuator name="panda_joint5_motor">
            <hardwareInterface>hardware_interface/EffortJointInterface</hardwareInterface>
            <mechanicalReduction>1</mechanicalReduction>
        </actuator>
    </transmission>
    <transmission name="trans_panda_joint6">
        <type>transmission_interface/SimpleTransmission</type>
        <joint name="panda_joint6">
            <hardwareInterface>hardware_interface/EffortJointInterface</hardwareInterface>
        </joint>
        <actuator name="panda_joint6_motor">
            <hardwareInterface>hardware_interface/EffortJointInterface</hardwareInterface>
            <mechanicalReduction>1</mechanicalReduction>
        </actuator>
    </transmission>
    <transmission name="trans_panda_joint7">
        <type>transmission_interface/SimpleTransmission</type>
        <joint name="panda_joint7">
            <hardwareInterface>hardware_interface/EffortJointInterface</hardwareInterface>
        </joint>
        <actuator name="panda_joint7_motor">
            <hardwareInterface>hardware_interface/EffortJointInterface</hardwareInterface>
            <mechanicalReduction>1</mechanicalReduction>
        </actuator>
    </transmission>
    <transmission name="trans_robotiq_2f140_left_outer_knuckle_joint">
        <type>transmission_interface/SimpleTransmission</type>
        <joint name="robotiq_2f140_left_outer_knuckle_joint">
            <hardwareInterface>hardware_interface/EffortJointInterface</hardwareInterface>
        </joint>
        <actuator name="robotiq_2f140_left_outer_knuckle_joint_motor">
            <hardwareInterface>hardware_interface/EffortJointInterface</hardwareInterface>
            <mechanicalReduction>1</mechanicalReduction>
        </actuator>
    </transmission>
    <transmission name="trans_robotiq_2f140_left_inner_knuckle_joint">
        <type>transmission_interface/SimpleTransmission</type>
        <joint name="robotiq_2f140_left_inner_knuckle_joint">
            <hardwareInterface>hardware_interface/EffortJointInterface</hardwareInterface>
        </joint>
        <actuator name="robotiq_2f140_left_inner_knuckle_joint_motor">
            <hardwareInterface>hardware_interface/EffortJointInterface</hardwareInterface>
            <mechanicalReduction>1</mechanicalReduction>
        </actuator>
    </transmission>
    <transmission name="trans_robotiq_2f140_left_inner_finger_joint">
        <type>transmission_interface/SimpleTransmission</type>
        <joint name="robotiq_2f140_left_inner_finger_joint">
            <hardwareInterface>hardware_interface/EffortJointInterface</hardwareInterface>
        </joint>
        <actuator name="robotiq_2f140_left_inner_finger_joint_motor">
            <hardwareInterface>hardware_interface/EffortJointInterface</hardwareInterface>
            <mechanicalReduction>1</mechanicalReduction>
        </actuator>
    </transmission>
    <transmission name="trans_robotiq_2f140_right_outer_knuckle_joint">
        <type>transmission_interface/SimpleTransmission</type>
        <joint name="robotiq_2f140_right_outer_knuckle_joint">
            <hardwareInterface>hardware_interface/EffortJointInterface</hardwareInterface>
        </joint>
        <actuator name="robotiq_2f140_right_outer_knuckle_joint_motor">
            <hardwareInterface>hardware_interface/EffortJointInterface</hardwareInterface>
            <mechanicalReduction>1</mechanicalReduction>
        </actuator>
    </transmission>
    <transmission name="trans_robotiq_2f140_right_inner_knuckle_joint">
        <type>transmission_interface/SimpleTransmission</type>
        <joint name="robotiq_2f140_right_inner_knuckle_joint">
            <hardwareInterface>hardware_interface/EffortJointInterface</hardwareInterface>
        </joint>
        <actuator name="robotiq_2f140_right_inner_knuckle_joint_motor">
            <hardwareInterface>hardware_interface/EffortJointInterface</hardwareInterface>
            <mechanicalReduction>1</mechanicalReduction>
        </actuator>
    </transmission>
    <transmission name="trans_robotiq_2f140_right_inner_finger_joint">
        <type>transmission_interface/SimpleTransmission</type>
        <joint name="robotiq_2f140_right_inner_finger_joint">
            <hardwareInterface>hardware_interface/EffortJointInterface</hardwareInterface>
        </joint>
        <actuator name="robotiq_2f140_right_inner_finger_joint_motor">
            <hardwareInterface>hardware_interface/EffortJointInterface</hardwareInterface>
            <mechanicalReduction>1</mechanicalReduction>
        </actuator>
    </transmission>
    <gazebo>
        <plugin name="gazebo_ros_control" filename="libgazebo_ros_control.so">
            <robotNamespace>/</robotNamespace>
        </plugin>
    </gazebo>
</robot>
